Workbook

Sheet 使い方
A1: アポ管理表（LINE・MEO）の使い方
A3: ■ 入力するのは5か所だけ
A4: ① 全体集計(入力)触るな(大阪)／(京都) …… アポインター・詰め直し・商談の結果（1行＝1アポ）。メニュー「ダービー貼付」から登録できます
A5: ② クローザー集計(入力)触るな …… クローザーの商談結果（大阪・京都共通、自アポ・紹介も含む）。商談メモ登録で自動追加。最終結果・月額・初期費用・ジアポは手入力
A6: ③ シフト入力 …… 1行＝1人×1日。提出（予定）と実際の出勤・退勤・休憩を入力すると稼働時間が自動計算
A7: ④ 設定 …… 対象月・営業日数・目標（大阪/京都）・想定の率・順位ルールの数値
A8: ⑤ マスタ …… メンバーと選択肢（シフト名簿の「シフトエリア」で、誰の稼働時間をどのエリアに入れるか決める）
A9: それ以外（IS進捗・FS進捗・合計サマリー・クローザーサマリー）は全部自動計算です。
A11: ■ 毎月の始め方
A12: 1. 前月のファイルの「月次実績」4行目を、下の空いている行に「値のみ貼り付け」して実績を残す
A13: 2. このファイルを「ひな形」として、ファイル → コピーを作成 で新しい月のファイルを作る（月次実績シートは前月ファイルからコピー）
A14: 3. 設定シートの「対象月」「営業日数」「目標」を更新
... A28: 黄色＝入力するセル ／ 青灰色＝自動計算 ／ 青文字＝設定値

Sheet IS進捗
A1: IS進捗（アポ）
A2: =TEXT(設定!$B$5,"yyyy年m月")&" 営業日 "&設定!$B$9&" / "&設定!$B$6&" 日目（残り "&設定!$B$10&" 日）" -> 2026年11月 営業日 0 / 21 日目（残り 21 日）
B4: エリア比較
B5: 項目 | C5: 大阪 | D5: 京都 | E5: 合計
B6: アポ件数 | C6: =F18 -> 0 | D6: =F44 -> 0 | E6: =C6+D6 -> 0
B7: 決済者アポ件数 | C7: =F19 -> 0 | D7: =F45 -> 0 | E7: =C7+D7 -> 0
B8: 決済詰めOK | C8: =F20 -> 0 | D8: =F46 -> 0 | E8: =C8+D8 -> 0
B9: 決済者商談実施数 | C9: =F22 -> 0 | D9: =F48 -> 0 | E9: =C9+D9 -> 0
B10: 受注数 | C10: =F24 -> 0 | D10: =F50 -> 0 | E10: =C10+D10 -> 0
B11: 実施待ち件数 | C11: =F23 -> 0 | D11: =F49 -> 0 | E11: =C11+D11 -> 0
B12: アポ件数（着地予想） | C12: =I18 -> 0 | D12: =I44 -> 0 | E12: =C12+D12 -> 0
B13: アポ件数進捗（着地÷目標） | C13: =I20 -> 0 | D13: =I46 -> 0 | E13: =IFERROR((I18+I44)/(C21+C47),0) -> 0
B14: 稼働時間（実際） | C14: =F29 -> 0 | D14: =F55 -> 0 | E14: =C14+D14 -> 0
B15: SPH | C15: =F30 -> 0 | D15: =F56 -> 0 | E15: =IFERROR((F18+F44)/(F29+F55),0) -> 0
B16: ■ 大阪
B17: 営業日数値・目標 | E17: IS現状数値 | H17: 予想数値（このペースの着地）
B18: 営業日数 | C18: =設定!$B$6 -> 21 | E18: アポ件数 | F18: =COUNTA('全体集計(入力)触るな(大阪)'!$L$2:$L$501) -> 0 | H18: アポ件数 | I18: =IFERROR(F18/C20*C18,0) -> 0
B19: 残り営業日数 | C19: =設定!$B$10 -> 21 | E19: 決済者アポ件数 | F19: =(COUNTIF('全体集計(入力)触るな(大阪)'!$L$2:$L$501,"決済")+COUNTIF('全体集計(入力)触るな(大阪)'!$L$2:$L$501,"外人(決済)")) -> 0 | H19: 決済者アポ件数 | I19: =IFERROR(F19/C20*C18,0) -> 0
B20: 稼働日数 | C20: =設定!$B$9 -> 0 | E20: 決済詰めOK | F20: =(COUNTIFS('全体集計(入力)触るな(大阪)'!$L$2:$L$501,"決済",'全体集計(入力)触るな(大阪)'!$Q$2:$Q$501,"OK")+COUNTIFS('全体集計(入力)触るな(大阪)'!$L$2:$L$501,"外人(決済)",'全体集計(入力)触るな(大阪)'!$Q$2:$Q$501,"OK")) -> 0 | H20: アポ件数進捗 | I20: =IFERROR(I18/C21,0) -> 0
B21: 目標アポ数 | C21: =設定!$B$13 -> 100 | E21: 詰め直し通過率 | F21: =IFERROR(F20/F19,0) -> 0 | H21: 決済者アポ件数進捗 | I21: =IFERROR(I19/C22,0) -> 0
B22: 目標決済アポ数 | C22: =設定!$B$14 -> 90 | E22: 決済者商談実施数 | F22: =COUNTIF('全体集計(入力)触るな(大阪)'!$Z$2:$Z$501,"決済者") -> 0 | H22: 決済詰めOK | I22: =I19*F21 -> 0
B23: 詰めOK数（目標） | C23: =C22*設定!$B$18 -> 63 | E23: 実施待ち件数（自動） | F23: =(COUNTIFS('全体集計(入力)触るな(大阪)'!$L$2:$L$501,"決済",'全体集計(入力)触るな(大阪)'!$Q$2:$Q$501,"OK",'全体集計(入力)触るな(大阪)'!$V$2:$V$501,"")+COUNTIFS('全体集計(入力)触るな(大阪)'!$L$2:$L$501,"外人(決済)",'全体集計(入力)触るな(大阪)'!$Q$2:$Q$501,"OK",'全体集計(入力)触るな(大阪)'!$V$2:$V$501,"")) -> 0 | H23: 決済者商談実施数 | I23: =I22*F25 -> 0
B24: 実施数（目標） | C24: =C23*設定!$B$19 -> 37.8 | E24: 受注数 | F24: =COUNTIF('全体集計(入力)触るな(大阪)'!$AF$2:$AF$501,"受注") -> 0 | H24: 受注数 | I24: =I23*F26 -> 0
B25: 受注数（目標） | C25: =C24*設定!$B$20 -> 18.9 | E25: 決済者商談実施率 | F25: =IFERROR(F22/(F20-F23),0) -> 0 | H25: 売上 | I25: =I24*設定!$B$22 -> 0
B26: 売上（目標） | C26: =C25*設定!$B$22 -> 472500 | E26: 決済者受注率 | F26: =IFERROR(F24/F22,0) -> 0
B28: 稼働時間・目標 | E28: 稼働時間・現状 | H28: 稼働時間・予想
B29: 予定稼働時間（シフト提出） | C29: =SUMIFS(シフト入力!$M$2:$M$1501,シフト入力!$C$2:$C$1501,"大阪") -> 0 | E29: 稼働時間（実際・今日まで） | F29: =SUMIFS(シフト入力!$N$2:$N$1501,シフト入力!$C$2:$C$1501,"大阪",シフト入力!$A$2:$A$1501,"<="&TODAY()) -> 0 | H29: アポ基準件数（目標SPH×稼働） | I29: =C30*F29 -> 0
B30: 目標SPH | C30: =設定!$B$15 -> 0.13 | E30: SPH（アポ÷稼働時間） | F30: =IFERROR(F18/F29,0) -> 0 | H30: アポ件数ショート数 | I30: =F18-I29 -> 0
B31: SPH×予定稼働時間 | C31: =C29*C30 -> 0 | E31: 予定稼働時間（今日まで） | F31: =SUMIFS(シフト入力!$M$2:$M$1501,シフト入力!$C$2:$C$1501,"大阪",シフト入力!$A$2:$A$1501,"<="&TODAY()) -> 0
E32: 稼働時間割合（実際÷予定） | F32: =IFERROR(F29/F31,0) -> 0
B42: ■ 京都
B43: 営業日数値・目標 | E43: IS現状数値 | H43: 予想数値（このペースの着地）
B44: 営業日数 | C44: =設定!$B$6 -> 21 | E44: アポ件数 | F44: =COUNTA('全体集計(入力)触るな(京都)'!$L$2:$L$501) -> 0 | H44: アポ件数 | I44: =IFERROR(F44/C46*C44,0) -> 0
B45: 残り営業日数 | C45: =設定!$B$10 -> 21 | E45: 決済者アポ件数 | F45: =(COUNTIF('全体集計(入力)触るな(京都)'!$L$2:$L$501,"決済")+COUNTIF('全体集計(入力)触るな(京都)'!$L$2:$L$501,"外人(決済)")) -> 0 | H45: 決済者アポ件数 | I45: =IFERROR(F45/C46*C44,0) -> 0
B46: 稼働日数 | C46: =設定!$B$9 -> 0 | E46: 決済詰めOK | F46: =(COUNTIFS('全体集計(入力)触るな(京都)'!$L$2:$L$501,"決済",'全体集計(入力)触るな(京都)'!$Q$2:$Q$501,"OK")+COUNTIFS('全体集計(入力)触るな(京都)'!$L$2:$L$501,"外人(決済)",'全体集計(入力)触るな(京都)'!$Q$2:$Q$501,"OK")) -> 0 | H46: アポ件数進捗 | I46: =IFERROR(I44/C47,0) -> 0
B47: 目標アポ数 | C47: =設定!$C$13 -> 40 | E47: 詰め直し通過率 | F47: =IFERROR(F46/F45,0) -> 0 | H47: 決済者アポ件数進捗 | I47: =IFERROR(I45/C48,0) -> 0
B48: 目標決済アポ数 | C48: =設定!$C$14 -> 35 | E48: 決済者商談実施数 | F48: =COUNTIF('全体集計(入力)触るな(京都)'!$Z$2:$Z$501,"決済者") -> 0 | H48: 決済詰めOK | I48: =I45*F47 -> 0
B49: 詰めOK数（目標） | C49: =C48*設定!$B$18 -> 24.5 | E49: 実施待ち件数（自動） | F49: =(COUNTIFS('全体集計(入力)触るな(京都)'!$L$2:$L$501,"決済",'全体集計(入力)触るな(京都)'!$Q$2:$Q$501,"OK",'全体集計(入力)触るな(京都)'!$V$2:$V$501,"")+COUNTIFS('全体集計(入力)触るな(京都)'!$L$2:$L$501,"外人(決済)",'全体集計(入力)触るな(京都)'!$Q$2:$Q$501,"OK",'全体集計(入力)触るな(京都)'!$V$2:$V$501,"")) -> 0 | H49: 決済者商談実施数 | I49: =I48*F51 -> 0
B50: 実施数（目標） | C50: =C49*設定!$B$19 -> 14.7 | E50: 受注数 | F50: =COUNTIF('全体集計(入力)触るな(京都)'!$AF$2:$AF$501,"受注") -> 0 | H50: 受注数 | I50: =I49*F52 -> 0
B51: 受注数（目標） | C51: =C50*設定!$B$20 -> 7.35 | E51: 決済者商談実施率 | F51: =IFERROR(F48/(F46-F49),0) -> 0 | H51: 売上 | I51: =I50*設定!$B$22 -> 0
...

Sheet FS進捗
A1: FS進捗（商談・受注／大阪＋京都）
A2: =IS進捗!A2 -> 2026年11月 営業日 0 / 21 日目（残り 21 日）
B4: 営業日数値・目標 | E4: FS現状数値 | H4: 想定数値（想定受注率で） | K4: 着地予想（実施待ちを含む）
B5: 営業日数 | C5: =設定!$B$6 -> 21 | E5: 商談割り当て数 | F5: =クローザーサマリー!$C$13 -> 0 | H5: 決済者商談実施数 | I5: =F6 -> 0 | K5: 決済者商談実施数 | L5: =F6+F8 -> 0
B6: 残り営業日数 | C6: =設定!$B$10 -> 21 | E6: 決済者商談実施数 | F6: =クローザーサマリー!$E$13 -> 0 | H6: 受注数 | I6: =I5*設定!$B$21 -> 0 | K6: 受注数 | L6: =L5*F10 -> 0
B7: 稼働日数 | C7: =設定!$B$9 -> 0 | E7: 実施待ち件数 | F7: =IS進捗!F23+IS進捗!F49 -> 0 | H7: 決済者受注率 | I7: =設定!$B$21 -> 0.35 | K7: 獲得平均単価 | L7: =F11 -> 0
B8: 目標実施数（大阪＋京都） | C8: =IS進捗!C24+IS進捗!C50 -> 52.5 | E8: 実施待ち×実施率 | F8: =F7*設定!$B$19 -> 0 | H8: 売上 | I8: =I6*設定!$B$22 -> 0 | K8: 売上 | L8: =L6*L7 -> 0
B9: 目標受注数 | C9: =C8*設定!$B$21 -> 18.375 | E9: 受注数 | F9: =クローザーサマリー!$F$13 -> 0 | H9: 売上進捗率 | I9: =IFERROR(I8/C10,0) -> 0 | K9: 売上進捗率 | L9: =IFERROR(L8/C10,0) -> 0
B10: 目標売上 | C10: =C9*設定!$B$22 -> 459375 | E10: 決済者受注率 | F10: =IFERROR(F9/F6,0) -> 0
B11: 目標実施の今日時点ペース | C11: =IFERROR(C8*C7/C5,0) -> 0 | E11: 獲得平均単価 | F11: =クローザーサマリー!$I$13 -> 0
B12: 営業日進捗率 | C12: =IFERROR(F6/C11,0) -> 0 | E12: 売上（クローザー合計） | F12: =クローザーサマリー!$R$13 -> 0
B13: ペース差分 | C13: =F6-C11 -> 0 | E13: 売上進捗率 | F13: =IFERROR(F12/C10,0) -> 0
B14: 売上ショート | C14: =F12-C10 -> -459375 | E14: 初期費用合計 | F14: =クローザーサマリー!$L$13 -> 0
E17: 初回結果（大阪＋京都）
E18: リスケ数 | F18: =(COUNTIF('全体集計(入力)触るな(大阪)'!$V$2:$V$501,"リスケ"))+(COUNTIF('全体集計(入力)触るな(京都)'!$V$2:$V$501,"リスケ")) -> 0
E19: 商談前キャンセル | F19: =(COUNTIF('全体集計(入力)触るな(大阪)'!$V$2:$V$501,"商談前キャンセル"))+(COUNTIF('全体集計(入力)触るな(京都)'!$V$2:$V$501,"商談前キャンセル")) -> 0
E20: リスケから実施 | F20: =((COUNTIFS('全体集計(入力)触るな(大阪)'!$V$2:$V$501,"リスケ",'全体集計(入力)触るな(大阪)'!$Z$2:$Z$501,"決済者")+COUNTIFS('全体集計(入力)触るな(大阪)'!$V$2:$V$501,"リスケ",'全体集計(入力)触るな(大阪)'!$Z$2:$Z$501,"非決済")))+((COUNTIFS('全体集計(入力)触るな(京都)'!$V$2:$V$501,"リスケ",'全体集計(入力)触るな(京都)'!$Z$2:$Z$501,"決済者")+COUNTIFS('全体集計(入力)触るな(京都)'!$V$2:$V$501,"リスケ",'全体集計(入力)触るな(京都)'!$Z$2:$Z$501,"非決済"))) -> 0
E21: リスケから調整率 | F21: =IFERROR(F20/F18,0) -> 0
E22: リスケからキャンセル数 | F22: =(COUNTIFS('全体集計(入力)触るな(大阪)'!$V$2:$V$501,"リスケ",'全体集計(入力)触るな(大阪)'!$AF$2:$AF$501,"商談キャンセル"))+(COUNTIFS('全体集計(入力)触るな(京都)'!$V$2:$V$501,"リスケ",'全体集計(入力)触るな(京都)'!$AF$2:$AF$501,"商談キャンセル")) -> 0
E23: リスケからキャンセル率 | F23: =IFERROR(F22/F18,0) -> 0
E25: ※ リスケからの実施は翌月末締めまで追う

Sheet 合計サマリー(大阪)
A1: 合計サマリー（大阪）
B3: 全体アポ数値
B4: アポ数 | C4: 詰め直しOK数 | D4: 決済詰めOK数 | E4: 詰め直しNG数 | F4: 決済者アポ | G4: 商談キャンセル | H4: リスケ数 | I4: 失注 | J4: 受注 | K4: アポ課金 | L4: 目標件数 | M4: 営業日数 | N4: 日割り目標 | O4: 残り日割り
B5: =COUNTA('全体集計(入力)触るな(大阪)'!$L$2:$L$501) -> 0 | C5: =COUNTIF('全体集計(入力)触るな(大阪)'!$Q$2:$Q$501,"OK") -> 0 | D5: =(COUNTIFS('全体集計(入力)触るな(大阪)'!$L$2:$L$501,"決済",'全体集計(入力)触るな(大阪)'!$Q$2:$Q$501,"OK")+COUNTIFS('全体集計(入力)触るな(大阪)'!$L$2:$L$501,"外人(決済)",'全体集計(入力)触るな(大阪)'!$Q$2:$Q$501,"OK")) -> 0 | E5: =COUNTIF('全体集計(入力)触るな(大阪)'!$Q$2:$Q$501,"NG") -> 0 | F5: =(COUNTIF('全体集計(入力)触るな(大阪)'!$L$2:$L$501,"決済")+COUNTIF('全体集計(入力)触るな(大阪)'!$L$2:$L$501,"外人(決済)")) -> 0 | G5: =COUNTIF('全体集計(入力)触るな(大阪)'!$AF$2:$AF$501,"商談キャンセル") -> 0 | H5: =COUNTIF('全体集計(入力)触るな(大阪)'!$V$2:$V$501,"リスケ") -> 0 | I5: =COUNTIF('全体集計(入力)触るな(大阪)'!$AF$2:$AF$501,"失注") -> 0 | J5: =COUNTIF('全体集計(入力)触るな(大阪)'!$AF$2:$AF$501,"受注") -> 0 | K5: =COUNTIF('全体集計(入力)触るな(大阪)'!$AC$2:$AC$501,"⚪︎") -> 0 | L5: =設定!$B$13 -> 100 | M5: =設定!$B$6 -> 21 | N5: =IFERROR(設定!$B$13/設定!$B$6,0) -> 4.7619048 | O5: =IFERROR((設定!$B$13-B5)/設定!$B$10,0) -> 4.7619048
B7: 全体商談数値
B8: 商談割り当て数 | C8: 商談実行数 | D8: リスケ数 | E8: 無効商談 | F8: 有効商談 | G8: 決済者 | H8: 非決済 | I8: 失注 | J8: 検討 | K8: 受注 | L8: 外人アポ | M8: 平均獲得プラン
B9: =(COUNTA('全体集計(入力)触るな(大阪)'!$U$2:$U$501)-COUNTIF('全体集計(入力)触るな(大阪)'!$U$2:$U$501,"事前リスケ")) -> 0 | C9: =(COUNTIF('全体集計(入力)触るな(大阪)'!$W$2:$W$501,"有効商談")+COUNTIF('全体集計(入力)触るな(大阪)'!$W$2:$W$501,"無効商談")) -> 0 | D9: =COUNTIF('全体集計(入力)触るな(大阪)'!$V$2:$V$501,"リスケ") -> 0 | E9: =COUNTIF('全体集計(入力)触るな(大阪)'!$W$2:$W$501,"無効商談") -> 0 | F9: =COUNTIF('全体集計(入力)触るな(大阪)'!$W$2:$W$501,"有効商談") -> 0 | G9: =COUNTIF('全体集計(入力)触るな(大阪)'!$Z$2:$Z$501,"決済者") -> 0 | H9: =COUNTIF('全体集計(入力)触るな(大阪)'!$Z$2:$Z$501,"非決済") -> 0 | I9: =COUNTIF('全体集計(入力)触るな(大阪)'!$AF$2:$AF$501,"失注") -> 0 | J9: =COUNTIF('全体集計(入力)触るな(大阪)'!$X$2:$X$501,"検討") -> 0 | K9: =COUNTIF('全体集計(入力)触るな(大阪)'!$AF$2:$AF$501,"受注") -> 0 | L9: =COUNTIF('全体集計(入力)触るな(大阪)'!$AG$2:$AG$501,"外人") -> 0 | M9: =IFERROR(AVERAGEIFS('全体集計(入力)触るな(大阪)'!$AD$2:$AD$501,'全体集計(入力)触るな(大阪)'!$AF$2:$AF$501,"受注"),0) -> 0
B11: 全体の率
B12: 詰め直しOK率 | C12: 決済詰めOK率 | D12: 詰め直しNG率 | E12: 商談実行率 | F12: 無効商談率 | G12: 有効商談率 | H12: リスケ率 | I12: 決済率 | J12: 非決済率 | K12: 失注率 | L12: 受注率 | M12: アポ課金率 | N12: 検討率
B13: =IFERROR(C5/B5,0) -> 0 | C13: =IFERROR(D5/F5,0) -> 0 | D13: =IFERROR(E5/B5,0) -> 0 | E13: =IFERROR(C9/B5,0) -> 0 | F13: =IFERROR(E9/C9,0) -> 0 | G13: =IFERROR(F9/C9,0) -> 0 | H13: =IFERROR(H5/B5,0) -> 0 | I13: =IFERROR(G9/C9,0) -> 0 | J13: =IFERROR(H9/C9,0) -> 0 | K13: =IFERROR(I9/C9,0) -> 0 | L13: =IFERROR(K9/C9,0) -> 0 | M13: =IFERROR(K5/C9,0) -> 0 | N13: =IFERROR(J9/C9,0) -> 0
B15: アポインター担当別数値（インセンティブ：受注した月額1万円につき1P／稼働時間はシフト入力の実際の時間）
B16: 担当者 | C16: アポ数 | D16: 決済アポ | E16: 非決済アポ | F16: うち外人 | G16: 詰め直しOK | H16: 決済詰めOK | I16: 詰め直しNG | J16: リスケ | K16: 商談実行 | L16: 有効商談 | M16: 無効商談 | N16: 商談キャンセル | O16: 決済者商談 | P16: 失注 | Q16: 有効商談＋失注 | R16: 有効商談＋検討 | S16: 受注 | T16: アポ課金 | U16: 合計獲得プラン | V16: インセンティブP | W16: 稼働時間 | X16: SPH | Y16: 詰めOK率 | Z16: アポ→受注率
B17: =IF(INDEX(マスタ!$A$2:$A$60,1)="","",INDEX(マスタ!$A$2:$A$60,1)) -> 宮田 | C17: =IF($B17="","",COUNTIFS('全体集計(入力)触るな(大阪)'!$M$2:$M$501,$B17,'全体集計(入力)触るな(大阪)'!$L$2:$L$501,"<>")) -> 0 | D17: =IF($B17="","",COUNTIFS('全体集計(入力)触るな(大阪)'!$M$2:$M$501,$B17,'全体集計(入力)触るな(大阪)'!$L$2:$L$501,"決済")+COUNTIFS('全体集計(入力)触るな(大阪)'!$M$2:$M$501,$B17,'全体集計(入力)触るな(大阪)'!$L$2:$L$501,"外人(決済)")) -> 0 | E17: =IF($B17="","",COUNTIFS('全体集計(入力)触るな(大阪)'!$M$2:$M$501,$B17,'全体集計(入力)触るな(大阪)'!$L$2:$L$501,"非決済")+COUNTIFS('全体集計(入力)触るな(大阪)'!$M$2:$M$501,$B17,'全体集計(入力)触るな(大阪)'!$L$2:$L$501,"外人(非決済)")) -> 0 | F17: =IF($B17="","",COUNTIFS('全体集計(入力)触るな(大阪)'!$M$2:$M$501,$B17,'全体集計(入力)触るな(大阪)'!$L$2:$L$501,"外人(決済)")+COUNTIFS('全体集計(入力)触るな(大阪)'!$M$2:$M$501,$B17,'全体集計(入力)触るな(大阪)'!$L$2:$L$501,"外人(非決済)")) -> 0 | G17: =IF($B17="","",COUNTIFS('全体集計(入力)触るな(大阪)'!$M$2:$M$501,$B17,'全体集計(入力)触るな(大阪)'!$Q$2:$Q$501,"OK")) -> 0 | H17: =IF($B17="","",COUNTIFS('全体集計(入力)触るな(大阪)'!$M$2:$M$501,$B17,'全体集計(入力)触るな(大阪)'!$L$2:$L$501,"決済",'全体集計(入力)触るな(大阪)'!$Q$2:$Q$501,"OK")+COUNTIFS('全体集計(入力)触るな(大阪)'!$M$2:$M$501,$B17,'全体集計(入力)触るな(大阪)'!$L$2:$L$501,"外人(決済)",'全体集計(入力)触るな(大阪)'!$Q$2:$Q$501,"OK")) -> 0 | I17: =IF($B17="","",COUNTIFS('全体集計(入力)触るな(大阪)'!$M$2:$M$501,$B17,'全体集計(入力)触るな(大阪)'!$Q$2:$Q$501,"NG")) -> 0 | J17: =IF($B17="","",COUNTIFS('全体集計(入力)触るな(大阪)'!$M$2:$M$501,$B17,'全体集計(入力)触るな(大阪)'!$V$2:$V$501,"リスケ")) -> 0 | K17: =IF($B17="","",COUNTIFS('全体集計(入力)触るな(大阪)'!$M$2:$M$501,$B17,'全体集計(入力)触るな(大阪)'!$W$2:$W$501,"有効商談")+COUNTIFS('全体集計(入力)触るな(大阪)'!$M$2:$M$501,$B17,'全体集計(入力)触るな(大阪)'!$W$2:$W$501,"無効商談")) -> 0 | L17: =IF($B17="","",COUNTIFS('全体集計(入力)触るな(大阪)'!$M$2:$M$501,$B17,'全体集計(入力)触るな(大阪)'!$W$2:$W$501,"有効商談")) -> 0 | M17: =IF($B17="","",COUNTIFS('全体集計(入力)触るな(大阪)'!$M$2:$M$501,$B17,'全体集計(入力)触るな(大阪)'!$W$2:$W$501,"無効商談")) -> 0 | N17: =IF($B17="","",COUNTIFS('全体集計(入力)触るな(大阪)'!$M$2:$M$501,$B17,'全体集計(入力)触るな(大阪)'!$AF$2:$AF$501,"商談キャンセル")) -> 0 | O17: =IF($B17="","",COUNTIFS('全体集計(入力)触るな(大阪)'!$M$2:$M$501,$B17,'全体集計(入力)触るな(大阪)'!$Z$2:$Z$501,"決済者")) -> 0 | P17: =IF($B17="","",COUNTIFS('全体集計(入力)触るな(大阪)'!$M$2:$M$501,$B17,'全体集計(入力)触るな(大阪)'!$AF$2:$AF$501,"失注")) -> 0 | Q17: =IF($B17="","",COUNTIFS('全体集計(入力)触るな(大阪)'!$M$2:$M$501,$B17,'全体集計(入力)触るな(大阪)'!$W$2:$W$501,"有効商談",'全体集計(入力)触るな(大阪)'!$AF$2:$AF$501,"失注")) -> 0 | R17: =IF($B17="","",COUNTIFS('全体集計(入力)触るな(大阪)'!$M$2:$M$501,$B17,'全体集計(入力)触るな(大阪)'!$W$2:$W$501,"有効商談",'全体集計(入力)触るな(大阪)'!$X$2:$X$501,"検討")) -> 0 | S17: =IF($B17="","",COUNTIFS('全体集計(入力)触るな(大阪)'!$M$2:$M$501,$B17,'全体集計(入力)触るな(大阪)'!$AF$2:$AF$501,"受注")) -> 0 | T17: =IF($B17="","",COUNTIFS('全体集計(入力)触るな(大阪)'!$M$2:$M$501,$B17,'全体集計(入力)触るな(大阪)'!$AC$2:$AC$501,"⚪︎")) -> 0 | U17: =IF($B17="","",SUMIFS('全体集計(入力)触るな(大阪)'!$AD$2:$AD$501,'全体集計(入力)触るな(大阪)'!$M$2:$M$501,$B17,'全体集計(入力)触るな(大阪)'!$AF$2:$AF$501,"受注")) -> 0 | V17: =IF($B17="","",INT(U17/10000)) -> 0 | W17: =IF($B17="","",SUMIFS(シフト入力!$N$2:$N$1501,シフト入力!$B$2:$B$1501,$B17,シフト入力!$A$2:$A$1501,"<="&TODAY())) -> 0 | X17: =IF($B17="","",IFERROR(C17/W17,0)) -> 0 | Y17: =IF($B17="","",IFERROR(G17/C17,0)) -> 0 | Z17: =IF($B17="","",IFERROR(S17/C17,0)) -> 0
B18: =IF(INDEX(マスタ!$A$2:$A$60,2)="","",INDEX(マスタ!$A$2:$A$60,2)) -> 石山 | C18: =IF($B18="","",COUNTIFS('全体集計(入力)触るな(大阪)'!$M$2:$M$501,$B18,'全体集計(入力)触るな(大阪)'!$L$2:$L$501,"<>")) -> 0 | D18: =IF($B18="","",COUNTIFS('全体集計(入力)触るな(大阪)'!$M$2:$M$501,$B18,'全体集計(入力)触るな(大阪)'!$L$2:$L$501,"決済")+COUNTIFS('全体集計(入力)触るな(大阪)'!$M$2:$M$501,$B18,'全体集計(入力)触るな(大阪)'!$L$2:$L$501,"外人(決済)")) -> 0 | E18: =IF($B18="","",COUNTIFS('全体集計(入力)触るな(大阪)'!$M$2:$M$501,$B18,'全体集計(入力)触るな(大阪)'!$L$2:$L$501,"非決済")+COUNTIFS('全体集計(入力)触るな(大阪)'!$M$2:$M$501,$B18,'全体集計(入力)触るな(大阪)'!$L$2:$L$501,"外人(非決済)")) -> 0 | F18: =IF($B18="","",COUNTIFS('全体集計(入力)触るな(大阪)'!$M$2:$M$501,$B18,'全体集計(入力)触るな(大阪)'!$L$2:$L$501,"外人(決済)")+COUNTIFS('全体集計(入力)触るな(大阪)'!$M$2:$M$501,$B18,'全体集計(入力)触るな(大阪)'!$L$2:$L$501,"外人(非決済)")) -> 0 | G18: =IF($B18="","",COUNTIFS('全体集計(入力)触るな(大阪)'!$M$2:$M$501,$B18,'全体集計(入力)触るな(大阪)'!$Q$2:$Q$501,"OK")) -> 0 | H18: =IF($B18="","",COUNTIFS('全体集計(入力)触るな(大阪)'!$M$2:$M$501,$B18,'全体集計(入力)触るな(大阪)'!$L$2:$L$501,"決済",'全体集計(入力)触るな(大阪)'!$Q$2:$Q$501,"OK")+COUNTIFS('全体集計(入力)触るな(大阪)'!$M$2:$M$501,$B18,'全体集計(入力)触るな(大阪)'!$L$2:$L$501,"外人(決済)",'全体集計(入力)触るな(大阪)'!$Q$2:$Q$501,"OK")) -> 0 | I18: =IF($B18="","",COUNTIFS('全体集計(入力)触るな(大阪)'!$M$2:$M$501,$B18,'全体集計(入力)触るな(大阪)'!$Q$2:$Q$501,"NG")) -> 0 | J18: =IF($B18="","",COUNTIFS('全体集計(入力)触るな(大阪)'!$M$2:$M$501,$B18,'全体集計(入力)触るな(大阪)'!$V$2:$V$501,"リスケ")) -> 0 | K18: =IF($B18="","",COUNTIFS('全体集計(入力)触るな(大阪)'!$M$2:$M$501,$B18,'全体集計(入力)触るな(大阪)'!$W$2:$W$501,"有効商談")+COUNTIFS('全体集計(入力)触るな(大阪)'!$M$2:$M$501,$B18,'全体集計(入力)触るな(大阪)'!$W$2:$W$501,"無効商談")) -> 0 | L18: =IF($B18="","",COUNTIFS('全体集計(入力)触るな(大阪)'!$M$2:$M$501,$B18,'全体集計(入力)触るな(大阪)'!$W$2:$W$501,"有効商談")) -> 0 | M18: =IF($B18="","",COUNTIFS('全体集計(入力)触るな(大阪)'!$M$2:$M$501,$B18,'全体集計(入力)触るな(大阪)'!$W$2:$W$501,"無効商談")) -> 0 | N18: =IF($B18="","",COUNTIFS('全体集計(入力)触るな(大阪)'!$M$2:$M$501,$B18,'全体集計(入力)触るな(大阪)'!$AF$2:$AF$501,"商談キャンセル")) -> 0 | O18: =IF($B18="","",COUNTIFS('全体集計(入力)触るな(大阪)'!$M$2:$M$501,$B18,'全体集計(入力)触るな(大阪)'!$Z$2:$Z$501,"決済者")) -> 0 | P18: =IF($B18="","",COUNTIFS('全体集計(入力)触るな(大阪)'!$M$2:$M$501,$B18,'全体集計(入力)触るな(大阪)'!$AF$2:$AF$501,"失注")) -> 0 | Q18: =IF($B18="","",COUNTIFS('全体集計(入力)触るな(大阪)'!$M$2:$M$501,$B18,'全体集計(入力)触るな(大阪)'!$W$2:$W$501,"有効商談",'全体集計(入力)触るな(大阪)'!$AF$2:$AF$501,"失注")) -> 0 | R18: =IF($B18="","",COUNTIFS('全体集計(入力)触るな(大阪)'!$M$2:$M$501,$B18,'全体集計(入力)触るな(大阪)'!$W$2:$W$501,"有効商談",'全体集計(入力)触るな(大阪)'!$X$2:$X$501,"検討")) -> 0 | S18: =IF($B18="","",COUNTIFS('全体集計(入力)触るな(大阪)'!$M$2:$M$501,$B18,'全体集計(入力)触るな(大阪)'!$AF$2:$AF$501,"受注")) -> 0 | T18: =IF($B18="","",COUNTIFS('全体集計(入力)触るな(大阪)'!$M$2:$M$501,$B18,'全体集計(入力)触るな(大阪)'!$AC$2:$AC$501,"⚪︎")) -> 0 | U18: =IF($B18="","",SUMIFS('全体集計(入力)触るな(大阪)'!$AD$2:$AD$501,'全体集計(入力)触るな(大阪)'!$M$2:$M$501,$B18,'全体集計(入力)触るな(大阪)'!$AF$2:$AF$501,"受注")) -> 0 | V18: =IF($B18="","",INT(U18/10000)) -> 0 | W18: =IF($B18="","",SUMIFS(シフト入力!$N$2:$N$1501,シフト入力!$B$2:$B$1501,$B18,シフト入力!$A$2:$A$1501,"<="&TODAY())) -> 0 | X18: =IF($B18="","",IFERROR(C18/W18,0)) -> 0 | Y18: =IF($B18="","",IFERROR(G18/C18,0)) -> 0 | Z18: =IF($B18="","",IFERROR(S18/C18,0)) -> 0
B19: =IF(INDEX(マスタ!$A$2:$A$60,3)="","",INDEX(マスタ!$A$2:$A$60,3)) -> 向井 | C19: =IF($B19="","",COUNTIFS('全体集計(入力)触るな(大阪)'!$M$2:$M$501,$B19,'全体集計(入力)触るな(大阪)'!$L$2:$L$501,"<>")) -> 0 | D19: =IF($B19="","",COUNTIFS('全体集計(入力)触るな(大阪)'!$M$2:$M$501,$B19,'全体集計(入力)触るな(大阪)'!$L$2:$L$501,"決済")+COUNTIFS('全体集計(入力)触るな(大阪)'!$M$2:$M$501,$B19,'全体集計(入力)触るな(大阪)'!$L$2:$L$501,"外人(決済)")) -> 0 | E19: =IF($B19="","",COUNTIFS('全体集計(入力)触るな(大阪)'!$M$2:$M$501,$B19,'全体集計(入力)触るな(大阪)'!$L$2:$L$501,"非決済")+COUNTIFS('全体集計(入力)触るな(大阪)'!$M$2:$M$501,$B19,'全体集計(入力)触るな(大阪)'!$L$2:$L$501,"外人(非決済)")) -> 0 | F19: =IF($B19="","",COUNTIFS('全体集計(入力)触るな(大阪)'!$M$2:$M$501,$B19,'全体集計(入力)触るな(大阪)'!$L$2:$L$501,"外人(決済)")+COUNTIFS('全体集計(入力)触るな(大阪)'!$M$2:$M$501,$B19,'全体集計(入力)触るな(大阪)'!$L$2:$L$501,"外人(非決済)")) -> 0 | G19: =IF($B19="","",COUNTIFS('全体集計(入力)触るな(大阪)'!$M$2:$M$501,$B19,'全体集計(入力)触るな(大阪)'!$Q$2:$Q$501,"OK")) -> 0 | H19: =IF($B19="","",COUNTIFS('全体集計(入力)触るな(大阪)'!$M$2:$M$501,$B19,'全体集計(入力)触るな(大阪)'!$L$2:$L$501,"決済",'全体集計(入力)触るな(大阪)'!$Q$2:$Q$501,"OK")+COUNTIFS('全体集計(入力)触るな(大阪)'!$M$2:$M$501,$B19,'全体集計(入力)触るな(大阪)'!$L$2:$L$501,"外人(決済)",'全体集計(入力)触るな(大阪)'!$Q$2:$Q$501,"OK")) -> 0 | I19: =IF($B19="","",COUNTIFS('全体集計(入力)触るな(大阪)'!$M$2:$M$501,$B19,'全体集計(入力)触るな(大阪)'!$Q$2:$Q$501,"NG")) -> 0 | J19: =IF($B19="","",COUNTIFS('全体集計(入力)触るな(大阪)'!$M$2:$M$501,$B19,'全体集計(入力)触るな(大阪)'!$V$2:$V$501,"リスケ")) -> 0 | K19: =IF($B19="","",COUNTIFS('全体集計(入力)触るな(大阪)'!$M$2:$M$501,$B19,'全体集計(入力)触るな(大阪)'!$W$2:$W$501,"有効商談")+COUNTIFS('全体集計(入力)触るな(大阪)'!$M$2:$M$501,$B19,'全体集計(入力)触るな(大阪)'!$W$2:$W$501,"無効商談")) -> 0 | L19: =IF($B19="","",COUNTIFS('全体集計(入力)触るな(大阪)'!$M$2:$M$501,$B19,'全体集計(入力)触るな(大阪)'!$W$2:$W$501,"有効商談")) -> 0 | M19: =IF($B19="","",COUNTIFS('全体集計(入力)触るな(大阪)'!$M$2:$M$501,$B19,'全体集計(入力)触るな(大阪)'!$W$2:$W$501,"無効商談")) -> 0 | N19: =IF($B19="","",COUNTIFS('全体集計(入力)触るな(大阪)'!$M$2:$M$501,$B19,'全体集計(入力)触るな(大阪)'!$AF$2:$AF$501,"商談キャンセル")) -> 0 | O19: =IF($B19="","",COUNTIFS('全体集計(入力)触るな(大阪)'!$M$2:$M$501,$B19,'全体集計(入力)触るな(大阪)'!$Z$2:$Z$501,"決済者")) -> 0 | P19: =IF($B19="","",COUNTIFS('全体集計(入力)触るな(大阪)'!$M$2:$M$501,$B19,'全体集計(入力)触るな(大阪)'!$AF$2:$AF$501,"失注")) -> 0 | Q19: =IF($B19="","",COUNTIFS('全体集計(入力)触るな(大阪)'!$M$2:$M$501,$B19,'全体集計(入力)触るな(大阪)'!$W$2:$W$501,"有効商談",'全体集計(入力)触るな(大阪)'!$AF$2:$AF$501,"失注")) -> 0 | R19: =IF($B19="","",COUNTIFS('全体集計(入力)触るな(大阪)'!$M$2:$M$501,$B19,'全体集計(入力)触るな(大阪)'!$W$2:$W$501,"有効商談",'全体集計(入力)触るな(大阪)'!$X$2:$X$501,"検討")) -> 0 | S19: =IF($B19="","",COUNTIFS('全体集計(入力)触るな(大阪)'!$M$2:$M$501,$B19,'全体集計(入力)触るな(大阪)'!$AF$2:$AF$501,"受注")) -> 0 | T19: =IF($B19="","",COUNTIFS('全体集計(入力)触るな(大阪)'!$M$2:$M$501,$B19,'全体集計(入力)触るな(大阪)'!$AC$2:$AC$501,"⚪︎")) -> 0 | U19: =IF($B19="","",SUMIFS('全体集計(入力)触るな(大阪)'!$AD$2:$AD$501,'全体集計(入力)触るな(大阪)'!$M$2:$M$501,$B19,'全体集計(入力)触るな(大阪)'!$AF$2:$AF$501,"受注")) -> 0 | V19: =IF($B19="","",INT(U19/10000)) -> 0 | W19: =IF($B19="","",SUMIFS(シフト入力!$N$2:$N$1501,シフト入力!$B$2:$B$1501,$B19,シフト入力!$A$2:$A$1501,"<="&TODAY())) -> 0 | X19: =IF($B19="","",IFERROR(C19/W19,0)) -> 0 | Y19: =IF($B19="","",IFERROR(G19/C19,0)) -> 0 | Z19: =IF($B19="","",IFERROR(S19/C19,0)) -> 0
B20: =IF(INDEX(マスタ!$A$2:$A$60,4)="","",INDEX(マスタ!$A$2:$A$60,4)) -> 中牟田 | C20: =IF($B20="","",COUNTIFS('全体集計(入力)触るな(大阪)'!$M$2:$M$501,$B20,'全体集計(入力)触るな(大阪)'!$L$2:$L$501,"<>")) -> 0 | D20: =IF($B20="","",COUNTIFS('全体集計(入力)触るな(大阪)'!$M$2:$M$501,$B20,'全体集計(入力)触るな(大阪)'!$L$2:$L$501,"決済")+COUNTIFS('全体集計(入力)触るな(大阪)'!$M$2:$M$501,$B20,'全体集計(入力)触るな(大阪)'!$L$2:$L$501,"外人(決済)")) -> 0 | E20: =IF($B20="","",COUNTIFS('全体集計(入力)触るな(大阪)'!$M$2:$M$501,$B20,'全体集計(入力)触るな(大阪)'!$L$2:$L$501,"非決済")+COUNTIFS('全体集計(入力)触るな(大阪)'!$M$2:$M$501,$B20,'全体集計(入力)触るな(大阪)'!$L$2:$L$501,"外人(非決済)")) -> 0 | F20: =IF($B20="","",COUNTIFS('全体集計(入力)触るな(大阪)'!$M$2:$M$501,$B20,'全体集計(入力)触るな(大阪)'!$L$2:$L$501,"外人(決済)")+COUNTIFS('全体集計(入力)触るな(大阪)'!$M$2:$M$501,$B20,'全体集計(入力)触るな(大阪)'!$L$2:$L$501,"外人(非決済)")) -> 0 | G20: =IF($B20="","",COUNTIFS('全体集計(入力)触るな(大阪)'!$M$2:$M$501,$B20,'全体集計(入力)触るな(大阪)'!$Q$2:$Q$501,"OK")) -> 0 | H20: =IF($B20="","",COUNTIFS('全体集計(入力)触るな(大阪)'!$M$2:$M$501,$B20,'全体集計(入力)触るな(大阪)'!$L$2:$L$501,"決済",'全体集計(入力)触るな(大阪)'!$Q$2:$Q$501,"OK")+COUNTIFS('全体集計(入力)触るな(大阪)'!$M$2:$M$501,$B20,'全体集計(入力)触るな(大阪)'!$L$2:$L$501,"外人(決済)",'全体集計(入力)触るな(大阪)'!$Q$2:$Q$501,"OK")) -> 0 | I20: =IF($B20="","",COUNTIFS('全体集計(入力)触るな(大阪)'!$M$2:$M$501,$B20,'全体集計(入力)触るな(大阪)'!$Q$2:$Q$501,"NG")) -> 0 | J20: =IF($B20="","",COUNTIFS('全体集計(入力)触るな(大阪)'!$M$2:$M$501,$B20,'全体集計(入力)触るな(大阪)'!$V$2:$V$501,"リスケ")) -> 0 | K20: =IF($B20="","",COUNTIFS('全体集計(入力)触るな(大阪)'!$M$2:$M$501,$B20,'全体集計(入力)触るな(大阪)'!$W$2:$W$501,"有効商談")+COUNTIFS('全体集計(入力)触るな(大阪)'!$M$2:$M$501,$B20,'全体集計(入力)触るな(大阪)'!$W$2:$W$501,"無効商談")) -> 0 | L20: =IF($B20="","",COUNTIFS('全体集計(入力)触るな(大阪)'!$M$2:$M$501,$B20,'全体集計(入力)触るな(大阪)'!$W$2:$W$501,"有効商談")) -> 0 | M20: =IF($B20="","",COUNTIFS('全体集計(入力)触るな(大阪)'!$M$2:$M$501,$B20,'全体集計(入力)触るな(大阪)'!$W$2:$W$501,"無効商談")) -> 0 | N20: =IF($B20="","",COUNTIFS('全体集計(入力)触るな(大阪)'!$M$2:$M$501,$B20,'全体集計(入力)触るな(大阪)'!$AF$2:$AF$501,"商談キャンセル")) -> 0 | O20: =IF($B20="","",COUNTIFS('全体集計(入力)触るな(大阪)'!$M$2:$M$501,$B20,'全体集計(入力)触るな(大阪)'!$Z$2:$Z$501,"決済者")) -> 0 | P20: =IF($B20="","",COUNTIFS('全体集計(入力)触るな(大阪)'!$M$2:$M$501,$B20,'全体集計(入力)触るな(大阪)'!$AF$2:$AF$501,"失注")) -> 0 | Q20: =IF($B20="","",COUNTIFS('全体集計(入力)触るな(大阪)'!$M$2:$M$501,$B20,'全体集計(入力)触るな(大阪)'!$W$2:$W$501,"有効商談",'全体集計(入力)触るな(大阪)'!$AF$2:$AF$501,"失注")) -> 0 | R20: =IF($B20="","",COUNTIFS('全体集計(入力)触るな(大阪)'!$M$2:$M$501,$B20,'全体集計(入力)触るな(大阪)'!$W$2:$W$501,"有効商談",'全体集計(入力)触るな(大阪)'!$X$2:$X$501,"検討")) -> 0 | S20: =IF($B20="","",COUNTIFS('全体集計(入力)触るな(大阪)'!$M$2:$M$501,$B20,'全体集計(入力)触るな(大阪)'!$AF$2:$AF$501,"受注")) -> 0 | T20: =IF($B20="","",COUNTIFS('全体集計(入力)触るな(大阪)'!$M$2:$M$501,$B20,'全体集計(入力)触るな(大阪)'!$AC$2:$AC$501,"⚪︎")) -> 0 | U20: =IF($B20="","",SUMIFS('全体集計(入力)触るな(大阪)'!$AD$2:$AD$501,'全体集計(入力)触るな(大阪)'!$M$2:$M$501,$B20,'全体集計(入力)触るな(大阪)'!$AF$2:$AF$501,"受注")) -> 0 | V20: =IF($B20="","",INT(U20/10000)) -> 0 | W20: =IF($B20="","",SUMIFS(シフト入力!$N$2:$N$1501,シフト入力!$B$2:$B$1501,$B20,シフト入力!$A$2:$A$1501,"<="&TODAY())) -> 0 | X20: =IF($B20="","",IFERROR(C20/W20,0)) -> 0 | Y20: =IF($B20="","",IFERROR(G20/C20,0)) -> 0 | Z20: =IF($B20="","",IFERROR(S20/C20,0)) -> 0
B21: =IF(INDEX(マスタ!$A$2:$A$60,5)="","",INDEX(マスタ!$A$2:$A$60,5)) -> 西川 | C21: =IF($B21="","",COUNTIFS('全体集計(入力)触るな(大阪)'!$M$2:$M$501,$B21,'全体集計(入力)触るな(大阪)'!$L$2:$L$501,"<>")) -> 0 | D21: =IF($B21="","",COUNTIFS('全体集計(入力)触るな(大阪)'!$M$2:$M$501,$B21,'全体集計(入力)触るな(大阪)'!$L$2:$L$501,"決済")+COUNTIFS('全体集計(入力)触るな(大阪)'!$M$2:$M$501,$B21,'全体集計(入力)触るな(大阪)'!$L$2:$L$501,"外人(決済)")) -> 0 | E21: =IF($B21="","",COUNTIFS('全体集計(入力)触るな(大阪)'!$M$2:$M$501,$B21,'全体集計(入力)触るな(大阪)'!$L$2:$L$501,"非決済")+COUNTIFS('全体集計(入力)触るな(大阪)'!$M$2:$M$501,$B21,'全体集計(入力)触るな(大阪)'!$L$2:$L$501,"外人(非決済)")) -> 0 | F21: =IF($B21="","",COUNTIFS('全体集計(入力)触るな(大阪)'!$M$2:$M$501,$B21,'全体集計(入力)触るな(大阪)'!$L$2:$L$501,"外人(決済)")+COUNTIFS('全体集計(入力)触るな(大阪)'!$M$2:$M$501,$B21,'全体集計(入力)触るな(大阪)'!$L$2:$L$501,"外人(非決済)")) -> 0 | G21: =IF($B21="","",COUNTIFS('全体集計(入力)触るな(大阪)'!$M$2:$M$501,$B21,'全体集計(入力)触るな(大阪)'!$Q$2:$Q$501,"OK")) -> 0 | H21: =IF($B21="","",COUNTIFS('全体集計(入力)触るな(大阪)'!$M$2:$M$501,$B21,'全体集計(入力)触るな(大阪)'!$L$2:$L$501,"決済",'全体集計(入力)触るな(大阪)'!$Q$2:$Q$501,"OK")+COUNTIFS('全体集計(入力)触るな(大阪)'!$M$2:$M$501,$B21,'全体集計(入力)触るな(大阪)'!$L$2:$L$501,"外人(決済)",'全体集計(入力)触るな(大阪)'!$Q$2:$Q$501,"OK")) -> 0 | I21: =IF($B21="","",COUNTIFS('全体集計(入力)触るな(大阪)'!$M$2:$M$501,$B21,'全体集計(入力)触るな(大阪)'!$Q$2:$Q$501,"NG")) -> 0 | J21: =IF($B21="","",COUNTIFS('全体集計(入力)触るな(大阪)'!$M$2:$M$501,$B21,'全体集計(入力)触るな(大阪)'!$V$2:$V$501,"リスケ")) -> 0 | K21: =IF($B21="","",COUNTIFS('全体集計(入力)触るな(大阪)'!$M$2:$M$501,$B21,'全体集計(入力)触るな(大阪)'!$W$2:$W$501,"有効商談")+COUNTIFS('全体集計(入力)触るな(大阪)'!$M$2:$M$501,$B21,'全体集計(入力)触るな(大阪)'!$W$2:$W$501,"無効商談")) -> 0 | L21: =IF($B21="","",COUNTIFS('全体集計(入力)触るな(大阪)'!$M$2:$M$501,$B21,'全体集計(入力)触るな(大阪)'!$W$2:$W$501,"有効商談")) -> 0 | M21: =IF($B21="","",COUNTIFS('全体集計(入力)触るな(大阪)'!$M$2:$M$501,$B21,'全体集計(入力)触るな(大阪)'!$W$2:$W$501,"無効商談")) -> 0 | N21: =IF($B21="","",COUNTIFS('全体集計(入力)触るな(大阪)'!$M$2:$M$501,$B21,'全体集計(入力)触るな(大阪)'!$AF$2:$AF$501,"商談キャンセル")) -> 0 | O21: =IF($B21="","",COUNTIFS('全体集計(入力)触るな(大阪)'!$M$2:$M$501,$B21,'全体集計(入力)触るな(大阪)'!$Z$2:$Z$501,"決済者")) -> 0 | P21: =IF($B21="","",COUNTIFS('全体集計(入力)触るな(大阪)'!$M$2:$M$501,$B21,'全体集計(入力)触るな(大阪)'!$AF$2:$AF$501,"失注")) -> 0 | Q21: =IF($B21="","",COUNTIFS('全体集計(入力)触るな(大阪)'!$M$2:$M$501,$B21,'全体集計(入力)触るな(大阪)'!$W$2:$W$501,"有効商談",'全体集計(入力)触るな(大阪)'!$AF$2:$AF$501,"失注")) -> 0 | R21: =IF($B21="","",COUNTIFS('全体集計(入力)触るな(大阪)'!$M$2:$M$501,$B21,'全体集計(入力)触るな(大阪)'!$W$2:$W$501,"有効商談",'全体集計(入力)触るな(大阪)'!$X$2:$X$501,"検討")) -> 0 | S21: =IF($B21="","",COUNTIFS('全体集計(入力)触るな(大阪)'!$M$2:$M$501,$B21,'全体集計(入力)触るな(大阪)'!$AF$2:$AF$501,"受注")) -> 0 | T21: =IF($B21="","",COUNTIFS('全体集計(入力)触るな(大阪)'!$M$2:$M$501,$B21,'全体集計(入力)触るな(大阪)'!$AC$2:$AC$501,"⚪︎")) -> 0 | U21: =IF($B21="","",SUMIFS('全体集計(入力)触るな(大阪)'!$AD$2:$AD$501,'全体集計(入力)触るな(大阪)'!$M$2:$M$501,$B21,'全体集計(入力)触るな(大阪)'!$AF$2:$AF$501,"受注")) -> 0 | V21: =IF($B21="","",INT(U21/10000)) -> 0 | W21: =IF($B21="","",SUMIFS(シフト入力!$N$2:$N$1501,シフト入力!$B$2:$B$1501,$B21,シフト入力!$A$2:$A$1501,"<="&TODAY())) -> 0 | X21: =IF($B21="","",IFERROR(C21/W21,0)) -> 0 | Y21: =IF($B21="","",IFERROR(G21/C21,0)) -> 0 | Z21: =IF($B21="","",IFERROR(S21/C21,0)) -> 0
B22: =IF(INDEX(マスタ!$A$2:$A$60,6)="","",INDEX(マスタ!$A$2:$A$60,6)) -> 木下 | C22: =IF($B22="","",COUNTIFS('全体集計(入力)触るな(大阪)'!$M$2:$M$501,$B22,'全体集計(入力)触るな(大阪)'!$L$2:$L$501,"<>")) -> 0 | D22: =IF($B22="","",COUNTIFS('全体集計(入力)触るな(大阪)'!$M$2:$M$501,$B22,'全体集計(入力)触るな(大阪)'!$L$2:$L$501,"決済")+COUNTIFS('全体集計(入力)触るな(大阪)'!$M$2:$M$501,$B22,'全体集計(入力)触るな(大阪)'!$L$2:$L$501,"外人(決済)")) -> 0 | E22: =IF($B22="","",COUNTIFS('全体集計(入力)触るな(大阪)'!$M$2:$M$501,$B22,'全体集計(入力)触るな(大阪)'!$L$2:$L$501,"非決済")+COUNTIFS('全体集計(入力)触るな(大阪)'!$M$2:$M$501,$B22,'全体集計(入力)触るな(大阪)'!$L$2:$L$501,"外人(非決済)")) -> 0 | F22: =IF($B22="","",COUNTIFS('全体集計(入力)触るな(大阪)'!$M$2:$M$501,$B22,'全体集計(入力)触るな(大阪)'!$L$2:$L$501,"外人(決済)")+COUNTIFS('全体集計(入力)触るな(大阪)'!$M$2:$M$501,$B22,'全体集計(入力)触るな(大阪)'!$L$2:$L$501,"外人(非決済)")) -> 0 | G22: =IF($B22="","",COUNTIFS('全体集計(入力)触るな(大阪)'!$M$2:$M$501,$B22,'全体集計(入力)触るな(大阪)'!$Q$2:$Q$501,"OK")) -> 0 | H22: =IF($B22="","",COUNTIFS('全体集計(入力)触るな(大阪)'!$M$2:$M$501,$B22,'全体集計(入力)触るな(大阪)'!$L$2:$L$501,"決済",'全体集計(入力)触るな(大阪)'!$Q$2:$Q$501,"OK")+COUNTIFS('全体集計(入力)触るな(大阪)'!$M$2:$M$501,$B22,'全体集計(入力)触るな(大阪)'!$L$2:$L$501,"外人(決済)",'全体集計(入力)触るな(大阪)'!$Q$2:$Q$501,"OK")) -> 0 | I22: =IF($B22="","",COUNTIFS('全体集計(入力)触るな(大阪)'!$M$2:$M$501,$B22,'全体集計(入力)触るな(大阪)'!$Q$2:$Q$501,"NG")) -> 0 | J22: =IF($B22="","",COUNTIFS('全体集計(入力)触るな(大阪)'!$M$2:$M$501,$B22,'全体集計(入力)触るな(大阪)'!$V$2:$V$501,"リスケ")) -> 0 | K22: =IF($B22="","",COUNTIFS('全体集計(入力)触るな(大阪)'!$M$2:$M$501,$B22,'全体集計(入力)触るな(大阪)'!$W$2:$W$501,"有効商談")+COUNTIFS('全体集計(入力)触るな(大阪)'!$M$2:$M$501,$B22,'全体集計(入力)触るな(大阪)'!$W$2:$W$501,"無効商談")) -> 0 | L22: =IF($B22="","",COUNTIFS('全体集計(入力)触るな(大阪)'!$M$2:$M$501,$B22,'全体集計(入力)触るな(大阪)'!$W$2:$W$501,"有効商談")) -> 0 | M22: =IF($B22="","",COUNTIFS('全体集計(入力)触るな(大阪)'!$M$2:$M$501,$B22,'全体集計(入力)触るな(大阪)'!$W$2:$W$501,"無効商談")) -> 0 | N22: =IF($B22="","",COUNTIFS('全体集計(入力)触るな(大阪)'!$M$2:$M$501,$B22,'全体集計(入力)触るな(大阪)'!$AF$2:$AF$501,"商談キャンセル")) -> 0 | O22: =IF($B22="","",COUNTIFS('全体集計(入力)触るな(大阪)'!$M$2:$M$501,$B22,'全体集計(入力)触るな(大阪)'!$Z$2:$Z$501,"決済者")) -> 0 | P22: =IF($B22="","",COUNTIFS('全体集計(入力)触るな(大阪)'!$M$2:$M$501,$B22,'全体集計(入力)触るな(大阪)'!$AF$2:$AF$501,"失注")) -> 0 | Q22: =IF($B22="","",COUNTIFS('全体集計(入力)触るな(大阪)'!$M$2:$M$501,$B22,'全体集計(入力)触るな(大阪)'!$W$2:$W$501,"有効商談",'全体集計(入力)触るな(大阪)'!$AF$2:$AF$501,"失注")) -> 0 | R22: =IF($B22="","",COUNTIFS('全体集計(入力)触るな(大阪)'!$M$2:$M$501,$B22,'全体集計(入力)触るな(大阪)'!$W$2:$W$501,"有効商談",'全体集計(入力)触るな(大阪)'!$X$2:$X$501,"検討")) -> 0 | S22: =IF($B22="","",COUNTIFS('全体集計(入力)触るな(大阪)'!$M$2:$M$501,$B22,'全体集計(入力)触るな(大阪)'!$AF$2:$AF$501,"受注")) -> 0 | T22: =IF($B22="","",COUNTIFS('全体集計(入力)触るな(大阪)'!$M$2:$M$501,$B22,'全体集計(入力)触るな(大阪)'!$AC$2:$AC$501,"⚪︎")) -> 0 | U22: =IF($B22="","",SUMIFS('全体集計(入力)触るな(大阪)'!$AD$2:$AD$501,'全体集計(入力)触るな(大阪)'!$M$2:$M$501,$B22,'全体集計(入力)触るな(大阪)'!$AF$2:$AF$501,"受注")) -> 0 | V22: =IF($B22="","",INT(U22/10000)) -> 0 | W22: =IF($B22="","",SUMIFS(シフト入力!$N$2:$N$1501,シフト入力!$B$2:$B$1501,$B22,シフト入力!$A$2:$A$1501,"<="&TODAY())) -> 0 | X22: =IF($B22="","",IFERROR(C22/W22,0)) -> 0 | Y22: =IF($B22="","",IFERROR(G22/C22,0)) -> 0 | Z22: =IF($B22="","",IFERROR(S22/C22,0)) -> 0
B23: =IF(INDEX(マスタ!$A$2:$A$60,7)="","",INDEX(マスタ!$A$2:$A$60,7)) -> 篠原 | C23: =IF($B23="","",COUNTIFS('全体集計(入力)触るな(大阪)'!$M$2:$M$501,$B23,'全体集計(入力)触るな(大阪)'!$L$2:$L$501,"<>")) -> 0 | D23: =IF($B23="","",COUNTIFS('全体集計(入力)触るな(大阪)'!$M$2:$M$501,$B23,'全体集計(入力)触るな(大阪)'!$L$2:$L$501,"決済")+COUNTIFS('全体集計(入力)触るな(大阪)'!$M$2:$M$501,$B23,'全体集計(入力)触るな(大阪)'!$L$2:$L$501,"外人(決済)")) -> 0 | E23: =IF($B23="","",COUNTIFS('全体集計(入力)触るな(大阪)'!$M$2:$M$501,$B23,'全体集計(入力)触るな(大阪)'!$L$2:$L$501,"非決済")+COUNTIFS('全体集計(入力)触るな(大阪)'!$M$2:$M$501,$B23,'全体集計(入力)触るな(大阪)'!$L$2:$L$501,"外人(非決済)")) -> 0 | F23: =IF($B23="","",COUNTIFS('全体集計(入力)触るな(大阪)'!$M$2:$M$501,$B23,'全体集計(入力)触るな(大阪)'!$L$2:$L$501,"外人(決済)")+COUNTIFS('全体集計(入力)触るな(大阪)'!$M$2:$M$501,$B23,'全体集計(入力)触るな(大阪)'!$L$2:$L$501,"外人(非決済)")) -> 0 | G23: =IF($B23="","",COUNTIFS('全体集計(入力)触るな(大阪)'!$M$2:$M$501,$B23,'全体集計(入力)触るな(大阪)'!$Q$2:$Q$501,"OK")) -> 0 | H23: =IF($B23="","",COUNTIFS('全体集計(入力)触るな(大阪)'!$M$2:$M$501,$B23,'全体集計(入力)触るな(大阪)'!$L$2:$L$501,"決済",'全体集計(入力)触るな(大阪)'!$Q$2:$Q$501,"OK")+COUNTIFS('全体集計(入力)触るな(大阪)'!$M$2:$M$501,$B23,'全体集計(入力)触るな(大阪)'!$L$2:$L$501,"外人(決済)",'全体集計(入力)触るな(大阪)'!$Q$2:$Q$501,"OK")) -> 0 | I23: =IF($B23="","",COUNTIFS('全体集計(入力)触るな(大阪)'!$M$2:$M$501,$B23,'全体集計(入力)触るな(大阪)'!$Q$2:$Q$501,"NG")) -> 0 | J23: =IF($B23="","",COUNTIFS('全体集計(入力)触るな(大阪)'!$M$2:$M$501,$B23,'全体集計(入力)触るな(大阪)'!$V$2:$V$501,"リスケ")) -> 0 | K23: =IF($B23="","",COUNTIFS('全体集計(入力)触るな(大阪)'!$M$2:$M$501,$B23,'全体集計(入力)触るな(大阪)'!$W$2:$W$501,"有効商談")+COUNTIFS('全体集計(入力)触るな(大阪)'!$M$2:$M$501,$B23,'全体集計(入力)触るな(大阪)'!$W$2:$W$501,"無効商談")) -> 0 | L23: =IF($B23="","",COUNTIFS('全体集計(入力)触るな(大阪)'!$M$2:$M$501,$B23,'全体集計(入力)触るな(大阪)'!$W$2:$W$501,"有効商談")) -> 0 | M23: =IF($B23="","",COUNTIFS('全体集計(入力)触るな(大阪)'!$M$2:$M$501,$B23,'全体集計(入力)触るな(大阪)'!$W$2:$W$501,"無効商談")) -> 0 | N23: =IF($B23="","",COUNTIFS('全体集計(入力)触るな(大阪)'!$M$2:$M$501,$B23,'全体集計(入力)触るな(大阪)'!$AF$2:$AF$501,"商談キャンセル")) -> 0 | O23: =IF($B23="","",COUNTIFS('全体集計(入力)触るな(大阪)'!$M$2:$M$501,$B23,'全体集計(入力)触るな(大阪)'!$Z$2:$Z$501,"決済者")) -> 0 | P23: =IF($B23="","",COUNTIFS('全体集計(入力)触るな(大阪)'!$M$2:$M$501,$B23,'全体集計(入力)触るな(大阪)'!$AF$2:$AF$501,"失注")) -> 0 | Q23: =IF($B23="","",COUNTIFS('全体集計(入力)触るな(大阪)'!$M$2:$M$501,$B23,'全体集計(入力)触るな(大阪)'!$W$2:$W$501,"有効商談",'全体集計(入力)触るな(大阪)'!$AF$2:$AF$501,"失注")) -> 0 | R23: =IF($B23="","",COUNTIFS('全体集計(入力)触るな(大阪)'!$M$2:$M$501,$B23,'全体集計(入力)触るな(大阪)'!$W$2:$W$501,"有効商談",'全体集計(入力)触るな(大阪)'!$X$2:$X$501,"検討")) -> 0 | S23: =IF($B23="","",COUNTIFS('全体集計(入力)触るな(大阪)'!$M$2:$M$501,$B23,'全体集計(入力)触るな(大阪)'!$AF$2:$AF$501,"受注")) -> 0 | T23: =IF($B23="","",COUNTIFS('全体集計(入力)触るな(大阪)'!$M$2:$M$501,$B23,'全体集計(入力)触るな(大阪)'!$AC$2:$AC$501,"⚪︎")) -> 0 | U23: =IF($B23="","",SUMIFS('全体集計(入力)触るな(大阪)'!$AD$2:$AD$501,'全体集計(入力)触るな(大阪)'!$M$2:$M$501,$B23,'全体集計(入力)触るな(大阪)'!$AF$2:$AF$501,"受注")) -> 0 | V23: =IF($B23="","",INT(U23/10000)) -> 0 | W23: =IF($B23="","",SUMIFS(シフト入力!$N$2:$N$1501,シフト入力!$B$2:$B$1501,$B23,シフト入力!$A$2:$A$1501,"<="&TODAY())) -> 0 | X23: =IF($B23="","",IFERROR(C23/W23,0)) -> 0 | Y23: =IF($B23="","",IFERROR(G23/C23,0)) -> 0 | Z23: =IF($B23="","",IFERROR(S23/C23,0)) -> 0
B24: =IF(INDEX(マスタ!$A$2:$A$60,8)="","",INDEX(マスタ!$A$2:$A$60,8)) -> CSアポ | C24: =IF($B24="","",COUNTIFS('全体集計(入力)触るな(大阪)'!$M$2:$M$501,$B24,'全体集計(入力)触るな(大阪)'!$L$2:$L$501,"<>")) -> 0 | D24: =IF($B24="","",COUNTIFS('全体集計(入力)触るな(大阪)'!$M$2:$M$501,$B24,'全体集計(入力)触るな(大阪)'!$L$2:$L$501,"決済")+COUNTIFS('全体集計(入力)触るな(大阪)'!$M$2:$M$501,$B24,'全体集計(入力)触るな(大阪)'!$L$2:$L$501,"外人(決済)")) -> 0 | E24: =IF($B24="","",COUNTIFS('全体集計(入力)触るな(大阪)'!$M$2:$M$501,$B24,'全体集計(入力)触るな(大阪)'!$L$2:$L$501,"非決済")+COUNTIFS('全体集計(入力)触るな(大阪)'!$M$2:$M$501,$B24,'全体集計(入力)触るな(大阪)'!$L$2:$L$501,"外人(非決済)")) -> 0 | F24: =IF($B24="","",COUNTIFS('全体集計(入力)触るな(大阪)'!$M$2:$M$501,$B24,'全体集計(入力)触るな(大阪)'!$L$2:$L$501,"外人(決済)")+COUNTIFS('全体集計(入力)触るな(大阪)'!$M$2:$M$501,$B24,'全体集計(入力)触るな(大阪)'!$L$2:$L$501,"外人(非決済)")) -> 0 | G24: =IF($B24="","",COUNTIFS('全体集計(入力)触るな(大阪)'!$M$2:$M$501,$B24,'全体集計(入力)触るな(大阪)'!$Q$2:$Q$501,"OK")) -> 0 | H24: =IF($B24="","",COUNTIFS('全体集計(入力)触るな(大阪)'!$M$2:$M$501,$B24,'全体集計(入力)触るな(大阪)'!$L$2:$L$501,"決済",'全体集計(入力)触るな(大阪)'!$Q$2:$Q$501,"OK")+COUNTIFS('全体集計(入力)触るな(大阪)'!$M$2:$M$501,$B24,'全体集計(入力)触るな(大阪)'!$L$2:$L$501,"外人(決済)",'全体集計(入力)触るな(大阪)'!$Q$2:$Q$501,"OK")) -> 0 | I24: =IF($B24="","",COUNTIFS('全体集計(入力)触るな(大阪)'!$M$2:$M$501,$B24,'全体集計(入力)触るな(大阪)'!$Q$2:$Q$501,"NG")) -> 0 | J24: =IF($B24="","",COUNTIFS('全体集計(入力)触るな(大阪)'!$M$2:$M$501,$B24,'全体集計(入力)触るな(大阪)'!$V$2:$V$501,"リスケ")) -> 0 | K24: =IF($B24="","",COUNTIFS('全体集計(入力)触るな(大阪)'!$M$2:$M$501,$B24,'全体集計(入力)触るな(大阪)'!$W$2:$W$501,"有効商談")+COUNTIFS('全体集計(入力)触るな(大阪)'!$M$2:$M$501,$B24,'全体集計(入力)触るな(大阪)'!$W$2:$W$501,"無効商談")) -> 0 | L24: =IF($B24="","",COUNTIFS('全体集計(入力)触るな(大阪)'!$M$2:$M$501,$B24,'全体集計(入力)触るな(大阪)'!$W$2:$W$501,"有効商談")) -> 0 | M24: =IF($B24="","",COUNTIFS('全体集計(入力)触るな(大阪)'!$M$2:$M$501,$B24,'全体集計(入力)触るな(大阪)'!$W$2:$W$501,"無効商談")) -> 0 | N24: =IF($B24="","",COUNTIFS('全体集計(入力)触るな(大阪)'!$M$2:$M$501,$B24,'全体集計(入力)触るな(大阪)'!$AF$2:$AF$501,"商談キャンセル")) -> 0 | O24: =IF($B24="","",COUNTIFS('全体集計(入力)触るな(大阪)'!$M$2:$M$501,$B24,'全体集計(入力)触るな(大阪)'!$Z$2:$Z$501,"決済者")) -> 0 | P24: =IF($B24="","",COUNTIFS('全体集計(入力)触るな(大阪)'!$M$2:$M$501,$B24,'全体集計(入力)触るな(大阪)'!$AF$2:$AF$501,"失注")) -> 0 | Q24: =IF($B24="","",COUNTIFS('全体集計(入力)触るな(大阪)'!$M$2:$M$501,$B24,'全体集計(入力)触るな(大阪)'!$W$2:$W$501,"有効商談",'全体集計(入力)触るな(大阪)'!$AF$2:$AF$501,"失注")) -> 0 | R24: =IF($B24="","",COUNTIFS('全体集計(入力)触るな(大阪)'!$M$2:$M$501,$B24,'全体集計(入力)触るな(大阪)'!$W$2:$W$501,"有効商談",'全体集計(入力)触るな(大阪)'!$X$2:$X$501,"検討")) -> 0 | S24: =IF($B24="","",COUNTIFS('全体集計(入力)触るな(大阪)'!$M$2:$M$501,$B24,'全体集計(入力)触るな(大阪)'!$AF$2:$AF$501,"受注")) -> 0 | T24: =IF($B24="","",COUNTIFS('全体集計(入力)触るな(大阪)'!$M$2:$M$501,$B24,'全体集計(入力)触るな(大阪)'!$AC$2:$AC$501,"⚪︎")) -> 0 | U24: =IF($B24="","",SUMIFS('全体集計(入力)触るな(大阪)'!$AD$2:$AD$501,'全体集計(入力)触るな(大阪)'!$M$2:$M$501,$B24,'全体集計(入力)触るな(大阪)'!$AF$2:$AF$501,"受注")) -> 0 | V24: =IF($B24="","",INT(U24/10000)) -> 0 | W24: =IF($B24="","",SUMIFS(シフト入力!$N$2:$N$1501,シフト入力!$B$2:$B$1501,$B24,シフト入力!$A$2:$A$1501,"<="&TODAY())) -> 0 | X24: =IF($B24="","",IFERROR(C24/W24,0)) -> 0 | Y24: =IF($B24="","",IFERROR(G24/C24,0)) -> 0 | Z24: =IF($B24="","",IFERROR(S24/C24,0)) -> 0
B25: =IF(INDEX(マスタ!$A$2:$A$60,9)="","",INDEX(マスタ!$A$2:$A$60,9)) -> 大場 | C25: =IF($B25="","",COUNTIFS('全体集計(入力)触るな(大阪)'!$M$2:$M$501,$B25,'全体集計(入力)触るな(大阪)'!$L$2:$L$501,"<>")) -> 0 | D25: =IF($B25="","",COUNTIFS('全体集計(入力)触るな(大阪)'!$M$2:$M$501,$B25,'全体集計(入力)触るな(大阪)'!$L$2:$L$501,"決済")+COUNTIFS('全体集計(入力)触るな(大阪)'!$M$2:$M$501,$B25,'全体集計(入力)触るな(大阪)'!$L$2:$L$501,"外人(決済)")) -> 0 | E25: =IF($B25="","",COUNTIFS('全体集計(入力)触るな(大阪)'!$M$2:$M$501,$B25,'全体集計(入力)触るな(大阪)'!$L$2:$L$501,"非決済")+COUNTIFS('全体集計(入力)触るな(大阪)'!$M$2:$M$501,$B25,'全体集計(入力)触るな(大阪)'!$L$2:$L$501,"外人(非決済)")) -> 0 | F25: =IF($B25="","",COUNTIFS('全体集計(入力)触るな(大阪)'!$M$2:$M$501,$B25,'全体集計(入力)触るな(大阪)'!$L$2:$L$501,"外人(決済)")+COUNTIFS('全体集計(入力)触るな(大阪)'!$M$2:$M$501,$B25,'全体集計(入力)触るな(大阪)'!$L$2:$L$501,"外人(非決済)")) -> 0 | G25: =IF($B25="","",COUNTIFS('全体集計(入力)触るな(大阪)'!$M$2:$M$501,$B25,'全体集計(入力)触るな(大阪)'!$Q$2:$Q$501,"OK")) -> 0 | H25: =IF($B25="","",COUNTIFS('全体集計(入力)触るな(大阪)'!$M$2:$M$501,$B25,'全体集計(入力)触るな(大阪)'!$L$2:$L$501,"決済",'全体集計(入力)触るな(大阪)'!$Q$2:$Q$501,"OK")+COUNTIFS('全体集計(入力)触るな(大阪)'!$M$2:$M$501,$B25,'全体集計(入力)触るな(大阪)'!$L$2:$L$501,"外人(決済)",'全体集計(入力)触るな(大阪)'!$Q$2:$Q$501,"OK")) -> 0 | I25: =IF($B25="","",COUNTIFS('全体集計(入力)触るな(大阪)'!$M$2:$M$501,$B25,'全体集計(入力)触るな(大阪)'!$Q$2:$Q$501,"NG")) -> 0 | J25: =IF($B25="","",COUNTIFS('全体集計(入力)触るな(大阪)'!$M$2:$M$501,$B25,'全体集計(入力)触るな(大阪)'!$V$2:$V$501,"リスケ")) -> 0 | K25: =IF($B25="","",COUNTIFS('全体集計(入力)触るな(大阪)'!$M$2:$M$501,$B25,'全体集計(入力)触るな(大阪)'!$W$2:$W$501,"有効商談")+COUNTIFS('全体集計(入力)触るな(大阪)'!$M$2:$M$501,$B25,'全体集計(入力)触るな(大阪)'!$W$2:$W$501,"無効商談")) -> 0 | L25: =IF($B25="","",COUNTIFS('全体集計(入力)触るな(大阪)'!$M$2:$M$501,$B25,'全体集計(入力)触るな(大阪)'!$W$2:$W$501,"有効商談")) -> 0 | M25: =IF($B25="","",COUNTIFS('全体集計(入力)触るな(大阪)'!$M$2:$M$501,$B25,'全体集計(入力)触るな(大阪)'!$W$2:$W$501,"無効商談")) -> 0 | N25: =IF($B25="","",COUNTIFS('全体集計(入力)触るな(大阪)'!$M$2:$M$501,$B25,'全体集計(入力)触るな(大阪)'!$AF$2:$AF$501,"商談キャンセル")) -> 0 | O25: =IF($B25="","",COUNTIFS('全体集計(入力)触るな(大阪)'!$M$2:$M$501,$B25,'全体集計(入力)触るな(大阪)'!$Z$2:$Z$501,"決済者")) -> 0 | P25: =IF($B25="","",COUNTIFS('全体集計(入力)触るな(大阪)'!$M$2:$M$501,$B25,'全体集計(入力)触るな(大阪)'!$AF$2:$AF$501,"失注")) -> 0 | Q25: =IF($B25="","",COUNTIFS('全体集計(入力)触るな(大阪)'!$M$2:$M$501,$B25,'全体集計(入力)触るな(大阪)'!$W$2:$W$501,"有効商談",'全体集計(入力)触るな(大阪)'!$AF$2:$AF$501,"失注")) -> 0 | R25: =IF($B25="","",COUNTIFS('全体集計(入力)触るな(大阪)'!$M$2:$M$501,$B25,'全体集計(入力)触るな(大阪)'!$W$2:$W$501,"有効商談",'全体集計(入力)触るな(大阪)'!$X$2:$X$501,"検討")) -> 0 | S25: =IF($B25="","",COUNTIFS('全体集計(入力)触るな(大阪)'!$M$2:$M$501,$B25,'全体集計(入力)触るな(大阪)'!$AF$2:$AF$501,"受注")) -> 0 | T25: =IF($B25="","",COUNTIFS('全体集計(入力)触るな(大阪)'!$M$2:$M$501,$B25,'全体集計(入力)触るな(大阪)'!$AC$2:$AC$501,"⚪︎")) -> 0 | U25: =IF($B25="","",SUMIFS('全体集計(入力)触るな(大阪)'!$AD$2:$AD$501,'全体集計(入力)触るな(大阪)'!$M$2:$M$501,$B25,'全体集計(入力)触るな(大阪)'!$AF$2:$AF$501,"受注")) -> 0 | V25: =IF($B25="","",INT(U25/10000)) -> 0 | W25: =IF($B25="","",SUMIFS(シフト入力!$N$2:$N$1501,シフト入力!$B$2:$B$1501,$B25,シフト入力!$A$2:$A$1501,"<="&TODAY())) -> 0 | X25: =IF($B25="","",IFERROR(C25/W25,0)) -> 0 | Y25: =IF($B25="","",IFERROR(G25/C25,0)) -> 0 | Z25: =IF($B25="","",IFERROR(S25/C25,0)) -> 0
B26: =IF(INDEX(マスタ!$A$2:$A$60,10)="","",INDEX(マスタ!$A$2:$A$60,10)) -> 村上 | C26: =IF($B26="","",COUNTIFS('全体集計(入力)触るな(大阪)'!$M$2:$M$501,$B26,'全体集計(入力)触るな(大阪)'!$L$2:$L$501,"<>")) -> 0 | D26: =IF($B26="","",COUNTIFS('全体集計(入力)触るな(大阪)'!$M$2:$M$501,$B26,'全体集計(入力)触るな(大阪)'!$L$2:$L$501,"決済")+COUNTIFS('全体集計(入力)触るな(大阪)'!$M$2:$M$501,$B26,'全体集計(入力)触るな(大阪)'!$L$2:$L$501,"外人(決済)")) -> 0 | E26: =IF($B26="","",COUNTIFS('全体集計(入力)触るな(大阪)'!$M$2:$M$501,$B26,'全体集計(入力)触るな(大阪)'!$L$2:$L$501,"非決済")+COUNTIFS('全体集計(入力)触るな(大阪)'!$M$2:$M$501,$B26,'全体集計(入力)触るな(大阪)'!$L$2:$L$501,"外人(非決済)")) -> 0 | F26: =IF($B26="","",COUNTIFS('全体集計(入力)触るな(大阪)'!$M$2:$M$501,$B26,'全体集計(入力)触るな(大阪)'!$L$2:$L$501,"外人(決済)")+COUNTIFS('全体集計(入力)触るな(大阪)'!$M$2:$M$501,$B26,'全体集計(入力)触るな(大阪)'!$L$2:$L$501,"外人(非決済)")) -> 0 | G26: =IF($B26="","",COUNTIFS('全体集計(入力)触るな(大阪)'!$M$2:$M$501,$B26,'全体集計(入力)触るな(大阪)'!$Q$2:$Q$501,"OK")) -> 0 | H26: =IF($B26="","",COUNTIFS('全体集計(入力)触るな(大阪)'!$M$2:$M$501,$B26,'全体集計(入力)触るな(大阪)'!$L$2:$L$501,"決済",'全体集計(入力)触るな(大阪)'!$Q$2:$Q$501,"OK")+COUNTIFS('全体集計(入力)触るな(大阪)'!$M$2:$M$501,$B26,'全体集計(入力)触るな(大阪)'!$L$2:$L$501,"外人(決済)",'全体集計(入力)触るな(大阪)'!$Q$2:$Q$501,"OK")) -> 0 | I26: =IF($B26="","",COUNTIFS('全体集計(入力)触るな(大阪)'!$M$2:$M$501,$B26,'全体集計(入力)触るな(大阪)'!$Q$2:$Q$501,"NG")) -> 0 | J26: =IF($B26="","",COUNTIFS('全体集計(入力)触るな(大阪)'!$M$2:$M$501,$B26,'全体集計(入力)触るな(大阪)'!$V$2:$V$501,"リスケ")) -> 0 | K26: =IF($B26="","",COUNTIFS('全体集計(入力)触るな(大阪)'!$M$2:$M$501,$B26,'全体集計(入力)触るな(大阪)'!$W$2:$W$501,"有効商談")+COUNTIFS('全体集計(入力)触るな(大阪)'!$M$2:$M$501,$B26,'全体集計(入力)触るな(大阪)'!$W$2:$W$501,"無効商談")) -> 0 | L26: =IF($B26="","",COUNTIFS('全体集計(入力)触るな(大阪)'!$M$2:$M$501,$B26,'全体集計(入力)触るな(大阪)'!$W$2:$W$501,"有効商談")) -> 0 | M26: =IF($B26="","",COUNTIFS('全体集計(入力)触るな(大阪)'!$M$2:$M$501,$B26,'全体集計(入力)触るな(大阪)'!$W$2:$W$501,"無効商談")) -> 0 | N26: =IF($B26="","",COUNTIFS('全体集計(入力)触るな(大阪)'!$M$2:$M$501,$B26,'全体集計(入力)触るな(大阪)'!$AF$2:$AF$501,"商談キャンセル")) -> 0 | O26: =IF($B26="","",COUNTIFS('全体集計(入力)触るな(大阪)'!$M$2:$M$501,$B26,'全体集計(入力)触るな(大阪)'!$Z$2:$Z$501,"決済者")) -> 0 | P26: =IF($B26="","",COUNTIFS('全体集計(入力)触るな(大阪)'!$M$2:$M$501,$B26,'全体集計(入力)触るな(大阪)'!$AF$2:$AF$501,"失注")) -> 0 | Q26: =IF($B26="","",COUNTIFS('全体集計(入力)触るな(大阪)'!$M$2:$M$501,$B26,'全体集計(入力)触るな(大阪)'!$W$2:$W$501,"有効商談",'全体集計(入力)触るな(大阪)'!$AF$2:$AF$501,"失注")) -> 0 | R26: =IF($B26="","",COUNTIFS('全体集計(入力)触るな(大阪)'!$M$2:$M$501,$B26,'全体集計(入力)触るな(大阪)'!$W$2:$W$501,"有効商談",'全体集計(入力)触るな(大阪)'!$X$2:$X$501,"検討")) -> 0 | S26: =IF($B26="","",COUNTIFS('全体集計(入力)触るな(大阪)'!$M$2:$M$501,$B26,'全体集計(入力)触るな(大阪)'!$AF$2:$AF$501,"受注")) -> 0 | T26: =IF($B26="","",COUNTIFS('全体集計(入力)触るな(大阪)'!$M$2:$M$501,$B26,'全体集計(入力)触るな(大阪)'!$AC$2:$AC$501,"⚪︎")) -> 0 | U26: =IF($B26="","",SUMIFS('全体集計(入力)触るな(大阪)'!$AD$2:$AD$501,'全体集計(入力)触るな(大阪)'!$M$2:$M$501,$B26,'全体集計(入力)触るな(大阪)'!$AF$2:$AF$501,"受注")) -> 0 | V26: =IF($B26="","",INT(U26/10000)) -> 0 | W26: =IF($B26="","",SUMIFS(シフト入力!$N$2:$N$1501,シフト入力!$B$2:$B$1501,$B26,シフト入力!$A$2:$A$1501,"<="&TODAY())) -> 0 | X26: =IF($B26="","",IFERROR(C26/W26,0)) -> 0 | Y26: =IF($B26="","",IFERROR(G26/C26,0)) -> 0 | Z26: =IF($B26="","",IFERROR(S26/C26,0)) -> 0
B27: =IF(INDEX(マスタ!$A$2:$A$60,11)="","",INDEX(マスタ!$A$2:$A$60,11)) -> 谷川(ゆ) | C27: =IF($B27="","",COUNTIFS('全体集計(入力)触るな(大阪)'!$M$2:$M$501,$B27,'全体集計(入力)触るな(大阪)'!$L$2:$L$501,"<>")) -> 0 | D27: =IF($B27="","",COUNTIFS('全体集計(入力)触るな(大阪)'!$M$2:$M$501,$B27,'全体集計(入力)触るな(大阪)'!$L$2:$L$501,"決済")+COUNTIFS('全体集計(入力)触るな(大阪)'!$M$2:$M$501,$B27,'全体集計(入力)触るな(大阪)'!$L$2:$L$501,"外人(決済)")) -> 0 | E27: =IF($B27="","",COUNTIFS('全体集計(入力)触るな(大阪)'!$M$2:$M$501,$B27,'全体集計(入力)触るな(大阪)'!$L$2:$L$501,"非決済")+COUNTIFS('全体集計(入力)触るな(大阪)'!$M$2:$M$501,$B27,'全体集計(入力)触るな(大阪)'!$L$2:$L$501,"外人(非決済)")) -> 0 | F27: =IF($B27="","",COUNTIFS('全体集計(入力)触るな(大阪)'!$M$2:$M$501,$B27,'全体集計(入力)触るな(大阪)'!$L$2:$L$501,"外人(決済)")+COUNTIFS('全体集計(入力)触るな(大阪)'!$M$2:$M$501,$B27,'全体集計(入力)触るな(大阪)'!$L$2:$L$501,"外人(非決済)")) -> 0 | G27: =IF($B27="","",COUNTIFS('全体集計(入力)触るな(大阪)'!$M$2:$M$501,$B27,'全体集計(入力)触るな(大阪)'!$Q$2:$Q$501,"OK")) -> 0 | H27: =IF($B27="","",COUNTIFS('全体集計(入力)触るな(大阪)'!$M$2:$M$501,$B27,'全体集計(入力)触るな(大阪)'!$L$2:$L$501,"決済",'全体集計(入力)触るな(大阪)'!$Q$2:$Q$501,"OK")+COUNTIFS('全体集計(入力)触るな(大阪)'!$M$2:$M$501,$B27,'全体集計(入力)触るな(大阪)'!$L$2:$L$501,"外人(決済)",'全体集計(入力)触るな(大阪)'!$Q$2:$Q$501,"OK")) -> 0 | I27: =IF($B27="","",COUNTIFS('全体集計(入力)触るな(大阪)'!$M$2:$M$501,$B27,'全体集計(入力)触るな(大阪)'!$Q$2:$Q$501,"NG")) -> 0 | J27: =IF($B27="","",COUNTIFS('全体集計(入力)触るな(大阪)'!$M$2:$M$501,$B27,'全体集計(入力)触るな(大阪)'!$V$2:$V$501,"リスケ")) -> 0 | K27: =IF($B27="","",COUNTIFS('全体集計(入力)触るな(大阪)'!$M$2:$M$501,$B27,'全体集計(入力)触るな(大阪)'!$W$2:$W$501,"有効商談")+COUNTIFS('全体集計(入力)触るな(大阪)'!$M$2:$M$501,$B27,'全体集計(入力)触るな(大阪)'!$W$2:$W$501,"無効商談")) -> 0 | L27: =IF($B27="","",COUNTIFS('全体集計(入力)触るな(大阪)'!$M$2:$M$501,$B27,'全体集計(入力)触るな(大阪)'!$W$2:$W$501,"有効商談")) -> 0 | M27: =IF($B27="","",COUNTIFS('全体集計(入力)触るな(大阪)'!$M$2:$M$501,$B27,'全体集計(入力)触るな(大阪)'!$W$2:$W$501,"無効商談")) -> 0 | N27: =IF($B27="","",COUNTIFS('全体集計(入力)触るな(大阪)'!$M$2:$M$501,$B27,'全体集計(入力)触るな(大阪)'!$AF$2:$AF$501,"商談キャンセル")) -> 0 | O27: =IF($B27="","",COUNTIFS('全体集計(入力)触るな(大阪)'!$M$2:$M$501,$B27,'全体集計(入力)触るな(大阪)'!$Z$2:$Z$501,"決済者")) -> 0 | P27: =IF($B27="","",COUNTIFS('全体集計(入力)触るな(大阪)'!$M$2:$M$501,$B27,'全体集計(入力)触るな(大阪)'!$AF$2:$AF$501,"失注")) -> 0 | Q27: =IF($B27="","",COUNTIFS('全体集計(入力)触るな(大阪)'!$M$2:$M$501,$B27,'全体集計(入力)触るな(大阪)'!$W$2:$W$501,"有効商談",'全体集計(入力)触るな(大阪)'!$AF$2:$AF$501,"失注")) -> 0 | R27: =IF($B27="","",COUNTIFS('全体集計(入力)触るな(大阪)'!$M$2:$M$501,$B27,'全体集計(入力)触るな(大阪)'!$W$2:$W$501,"有効商談",'全体集計(入力)触るな(大阪)'!$X$2:$X$501,"検討")) -> 0 | S27: =IF($B27="","",COUNTIFS('全体集計(入力)触るな(大阪)'!$M$2:$M$501,$B27,'全体集計(入力)触るな(大阪)'!$AF$2:$AF$501,"受注")) -> 0 | T27: =IF($B27="","",COUNTIFS('全体集計(入力)触るな(大阪)'!$M$2:$M$501,$B27,'全体集計(入力)触るな(大阪)'!$AC$2:$AC$501,"⚪︎")) -> 0 | U27: =IF($B27="","",SUMIFS('全体集計(入力)触るな(大阪)'!$AD$2:$AD$501,'全体集計(入力)触るな(大阪)'!$M$2:$M$501,$B27,'全体集計(入力)触るな(大阪)'!$AF$2:$AF$501,"受注")) -> 0 | V27: =IF($B27="","",INT(U27/10000)) -> 0 | W27: =IF($B27="","",SUMIFS(シフト入力!$N$2:$N$1501,シフト入力!$B$2:$B$1501,$B27,シフト入力!$A$2:$A$1501,"<="&TODAY())) -> 0 | X27: =IF($B27="","",IFERROR(C27/W27,0)) -> 0 | Y27: =IF($B27="","",IFERROR(G27/C27,0)) -> 0 | Z27: =IF($B27="","",IFERROR(S27/C27,0)) -> 0
B28: =IF(INDEX(マスタ!$A$2:$A$60,12)="","",INDEX(マスタ!$A$2:$A$60,12)) -> 金本 | C28: =IF($B28="","",COUNTIFS('全体集計(入力)触るな(大阪)'!$M$2:$M$501,$B28,'全体集計(入力)触るな(大阪)'!$L$2:$L$501,"<>")) -> 0 | D28: =IF($B28="","",COUNTIFS('全体集計(入力)触るな(大阪)'!$M$2:$M$501,$B28,'全体集計(入力)触るな(大阪)'!$L$2:$L$501,"決済")+COUNTIFS('全体集計(入力)触るな(大阪)'!$M$2:$M$501,$B28,'全体集計(入力)触るな(大阪)'!$L$2:$L$501,"外人(決済)")) -> 0 | E28: =IF($B28="","",COUNTIFS('全体集計(入力)触るな(大阪)'!$M$2:$M$501,$B28,'全体集計(入力)触るな(大阪)'!$L$2:$L$501,"非決済")+COUNTIFS('全体集計(入力)触るな(大阪)'!$M$2:$M$501,$B28,'全体集計(入力)触るな(大阪)'!$L$2:$L$501,"外人(非決済)")) -> 0 | F28: =IF($B28="","",COUNTIFS('全体集計(入力)触るな(大阪)'!$M$2:$M$501,$B28,'全体集計(入力)触るな(大阪)'!$L$2:$L$501,"外人(決済)")+COUNTIFS('全体集計(入力)触るな(大阪)'!$M$2:$M$501,$B28,'全体集計(入力)触るな(大阪)'!$L$2:$L$501,"外人(非決済)")) -> 0 | G28: =IF($B28="","",COUNTIFS('全体集計(入力)触るな(大阪)'!$M$2:$M$501,$B28,'全体集計(入力)触るな(大阪)'!$Q$2:$Q$501,"OK")) -> 0 | H28: =IF($B28="","",COUNTIFS('全体集計(入力)触るな(大阪)'!$M$2:$M$501,$B28,'全体集計(入力)触るな(大阪)'!$L$2:$L$501,"決済",'全体集計(入力)触るな(大阪)'!$Q$2:$Q$501,"OK")+COUNTIFS('全体集計(入力)触るな(大阪)'!$M$2:$M$501,$B28,'全体集計(入力)触るな(大阪)'!$L$2:$L$501,"外人(決済)",'全体集計(入力)触るな(大阪)'!$Q$2:$Q$501,"OK")) -> 0 | I28: =IF($B28="","",COUNTIFS('全体集計(入力)触るな(大阪)'!$M$2:$M$501,$B28,'全体集計(入力)触るな(大阪)'!$Q$2:$Q$501,"NG")) -> 0 | J28: =IF($B28="","",COUNTIFS('全体集計(入力)触るな(大阪)'!$M$2:$M$501,$B28,'全体集計(入力)触るな(大阪)'!$V$2:$V$501,"リスケ")) -> 0 | K28: =IF($B28="","",COUNTIFS('全体集計(入力)触るな(大阪)'!$M$2:$M$501,$B28,'全体集計(入力)触るな(大阪)'!$W$2:$W$501,"有効商談")+COUNTIFS('全体集計(入力)触るな(大阪)'!$M$2:$M$501,$B28,'全体集計(入力)触るな(大阪)'!$W$2:$W$501,"無効商談")) -> 0 | L28: =IF($B28="","",COUNTIFS('全体集計(入力)触るな(大阪)'!$M$2:$M$501,$B28,'全体集計(入力)触るな(大阪)'!$W$2:$W$501,"有効商談")) -> 0 | M28: =IF($B28="","",COUNTIFS('全体集計(入力)触るな(大阪)'!$M$2:$M$501,$B28,'全体集計(入力)触るな(大阪)'!$W$2:$W$501,"無効商談")) -> 0 | N28: =IF($B28="","",COUNTIFS('全体集計(入力)触るな(大阪)'!$M$2:$M$501,$B28,'全体集計(入力)触るな(大阪)'!$AF$2:$AF$501,"商談キャンセル")) -> 0 | O28: =IF($B28="","",COUNTIFS('全体集計(入力)触るな(大阪)'!$M$2:$M$501,$B28,'全体集計(入力)触るな(大阪)'!$Z$2:$Z$501,"決済者")) -> 0 | P28: =IF($B28="","",COUNTIFS('全体集計(入力)触るな(大阪)'!$M$2:$M$501,$B28,'全体集計(入力)触るな(大阪)'!$AF$2:$AF$501,"失注")) -> 0 | Q28: =IF($B28="","",COUNTIFS('全体集計(入力)触るな(大阪)'!$M$2:$M$501,$B28,'全体集計(入力)触るな(大阪)'!$W$2:$W$501,"有効商談",'全体集計(入力)触るな(大阪)'!$AF$2:$AF$501,"失注")) -> 0 | R28: =IF($B28="","",COUNTIFS('全体集計(入力)触るな(大阪)'!$M$2:$M$501,$B28,'全体集計(入力)触るな(大阪)'!$W$2:$W$501,"有効商談",'全体集計(入力)触るな(大阪)'!$X$2:$X$501,"検討")) -> 0 | S28: =IF($B28="","",COUNTIFS('全体集計(入力)触るな(大阪)'!$M$2:$M$501,$B28,'全体集計(入力)触るな(大阪)'!$AF$2:$AF$501,"受注")) -> 0 | T28: =IF($B28="","",COUNTIFS('全体集計(入力)触るな(大阪)'!$M$2:$M$501,$B28,'全体集計(入力)触るな(大阪)'!$AC$2:$AC$501,"⚪︎")) -> 0 | U28: =IF($B28="","",SUMIFS('全体集計(入力)触るな(大阪)'!$AD$2:$AD$501,'全体集計(入力)触るな(大阪)'!$M$2:$M$501,$B28,'全体集計(入力)触るな(大阪)'!$AF$2:$AF$501,"受注")) -> 0 | V28: =IF($B28="","",INT(U28/10000)) -> 0 | W28: =IF($B28="","",SUMIFS(シフト入力!$N$2:$N$1501,シフト入力!$B$2:$B$1501,$B28,シフト入力!$A$2:$A$1501,"<="&TODAY())) -> 0 | X28: =IF($B28="","",IFERROR(C28/W28,0)) -> 0 | Y28: =IF($B28="","",IFERROR(G28/C28,0)) -> 0 | Z28: =IF($B28="","",IFERROR(S28/C28,0)) -> 0
B29: =IF(INDEX(マスタ!$A$2:$A$60,13)="","",INDEX(マスタ!$A$2:$A$60,13)) -> 岩本 | C29: =IF($B29="","",COUNTIFS('全体集計(入力)触るな(大阪)'!$M$2:$M$501,$B29,'全体集計(入力)触るな(大阪)'!$L$2:$L$501,"<>")) -> 0 | D29: =IF($B29="","",COUNTIFS('全体集計(入力)触るな(大阪)'!$M$2:$M$501,$B29,'全体集計(入力)触るな(大阪)'!$L$2:$L$501,"決済")+COUNTIFS('全体集計(入力)触るな(大阪)'!$M$2:$M$501,$B29,'全体集計(入力)触るな(大阪)'!$L$2:$L$501,"外人(決済)")) -> 0 | E29: =IF($B29="","",COUNTIFS('全体集計(入力)触るな(大阪)'!$M$2:$M$501,$B29,'全体集計(入力)触るな(大阪)'!$L$2:$L$501,"非決済")+COUNTIFS('全体集計(入力)触るな(大阪)'!$M$2:$M$501,$B29,'全体集計(入力)触るな(大阪)'!$L$2:$L$501,"外人(非決済)")) -> 0 | F29: =IF($B29="","",COUNTIFS('全体集計(入力)触るな(大阪)'!$M$2:$M$501,$B29,'全体集計(入力)触るな(大阪)'!$L$2:$L$501,"外人(決済)")+COUNTIFS('全体集計(入力)触るな(大阪)'!$M$2:$M$501,$B29,'全体集計(入力)触るな(大阪)'!$L$2:$L$501,"外人(非決済)")) -> 0 | G29: =IF($B29="","",COUNTIFS('全体集計(入力)触るな(大阪)'!$M$2:$M$501,$B29,'全体集計(入力)触るな(大阪)'!$Q$2:$Q$501,"OK")) -> 0 | H29: =IF($B29="","",COUNTIFS('全体集計(入力)触るな(大阪)'!$M$2:$M$501,$B29,'全体集計(入力)触るな(大阪)'!$L$2:$L$501,"決済",'全体集計(入力)触るな(大阪)'!$Q$2:$Q$501,"OK")+COUNTIFS('全体集計(入力)触るな(大阪)'!$M$2:$M$501,$B29,'全体集計(入力)触るな(大阪)'!$L$2:$L$501,"外人(決済)",'全体集計(入力)触るな(大阪)'!$Q$2:$Q$501,"OK")) -> 0 | I29: =IF($B29="","",COUNTIFS('全体集計(入力)触るな(大阪)'!$M$2:$M$501,$B29,'全体集計(入力)触るな(大阪)'!$Q$2:$Q$501,"NG")) -> 0 | J29: =IF($B29="","",COUNTIFS('全体集計(入力)触るな(大阪)'!$M$2:$M$501,$B29,'全体集計(入力)触るな(大阪)'!$V$2:$V$501,"リスケ")) -> 0 | K29: =IF($B29="","",COUNTIFS('全体集計(入力)触るな(大阪)'!$M$2:$M$501,$B29,'全体集計(入力)触るな(大阪)'!$W$2:$W$501,"有効商談")+COUNTIFS('全体集計(入力)触るな(大阪)'!$M$2:$M$501,$B29,'全体集計(入力)触るな(大阪)'!$W$2:$W$501,"無効商談")) -> 0 | L29: =IF($B29="","",COUNTIFS('全体集計(入力)触るな(大阪)'!$M$2:$M$501,$B29,'全体集計(入力)触るな(大阪)'!$W$2:$W$501,"有効商談")) -> 0 | M29: =IF($B29="","",COUNTIFS('全体集計(入力)触るな(大阪)'!$M$2:$M$501,$B29,'全体集計(入力)触るな(大阪)'!$W$2:$W$501,"無効商談")) -> 0 | N29: =IF($B29="","",COUNTIFS('全体集計(入力)触るな(大阪)'!$M$2:$M$501,$B29,'全体集計(入力)触るな(大阪)'!$AF$2:$AF$501,"商談キャンセル")) -> 0 | O29: =IF($B29="","",COUNTIFS('全体集計(入力)触るな(大阪)'!$M$2:$M$501,$B29,'全体集計(入力)触るな(大阪)'!$Z$2:$Z$501,"決済者")) -> 0 | P29: =IF($B29="","",COUNTIFS('全体集計(入力)触るな(大阪)'!$M$2:$M$501,$B29,'全体集計(入力)触るな(大阪)'!$AF$2:$AF$501,"失注")) -> 0 | Q29: =IF($B29="","",COUNTIFS('全体集計(入力)触るな(大阪)'!$M$2:$M$501,$B29,'全体集計(入力)触るな(大阪)'!$W$2:$W$501,"有効商談",'全体集計(入力)触るな(大阪)'!$AF$2:$AF$501,"失注")) -> 0 | R29: =IF($B29="","",COUNTIFS('全体集計(入力)触るな(大阪)'!$M$2:$M$501,$B29,'全体集計(入力)触るな(大阪)'!$W$2:$W$501,"有効商談",'全体集計(入力)触るな(大阪)'!$X$2:$X$501,"検討")) -> 0 | S29: =IF($B29="","",COUNTIFS('全体集計(入力)触るな(大阪)'!$M$2:$M$501,$B29,'全体集計(入力)触るな(大阪)'!$AF$2:$AF$501,"受注")) -> 0 | T29: =IF($B29="","",COUNTIFS('全体集計(入力)触るな(大阪)'!$M$2:$M$501,$B29,'全体集計(入力)触るな(大阪)'!$AC$2:$AC$501,"⚪︎")) -> 0 | U29: =IF($B29="","",SUMIFS('全体集計(入力)触るな(大阪)'!$AD$2:$AD$501,'全体集計(入力)触るな(大阪)'!$M$2:$M$501,$B29,'全体集計(入力)触るな(大阪)'!$AF$2:$AF$501,"受注")) -> 0 | V29: =IF($B29="","",INT(U29/10000)) -> 0 | W29: =IF($B29="","",SUMIFS(シフト入力!$N$2:$N$1501,シフト入力!$B$2:$B$1501,$B29,シフト入力!$A$2:$A$1501,"<="&TODAY())) -> 0 | X29: =IF($B29="","",IFERROR(C29/W29,0)) -> 0 | Y29: =IF($B29="","",IFERROR(G29/C29,0)) -> 0 | Z29: =IF($B29="","",IFERROR(S29/C29,0)) -> 0
B30: =IF(INDEX(マスタ!$A$2:$A$60,14)="","",INDEX(マスタ!$A$2:$A$60,14)) -> 谷川(と) | C30: =IF($B30="","",COUNTIFS('全体集計(入力)触るな(大阪)'!$M$2:$M$501,$B30,'全体集計(入力)触るな(大阪)'!$L$2:$L$501,"<>")) -> 0 | D30: =IF($B30="","",COUNTIFS('全体集計(入力)触るな(大阪)'!$M$2:$M$501,$B30,'全体集計(入力)触るな(大阪)'!$L$2:$L$501,"決済")+COUNTIFS('全体集計(入力)触るな(大阪)'!$M$2:$M$501,$B30,'全体集計(入力)触るな(大阪)'!$L$2:$L$501,"外人(決済)")) -> 0 | E30: =IF($B30="","",COUNTIFS('全体集計(入力)触るな(大阪)'!$M$2:$M$501,$B30,'全体集計(入力)触るな(大阪)'!$L$2:$L$501,"非決済")+COUNTIFS('全体集計(入力)触るな(大阪)'!$M$2:$M$501,$B30,'全体集計(入力)触るな(大阪)'!$L$2:$L$501,"外人(非決済)")) -> 0 | F30: =IF($B30="","",COUNTIFS('全体集計(入力)触るな(大阪)'!$M$2:$M$501,$B30,'全体集計(入力)触るな(大阪)'!$L$2:$L$501,"外人(決済)")+COUNTIFS('全体集計(入力)触るな(大阪)'!$M$2:$M$501,$B30,'全体集計(入力)触るな(大阪)'!$L$2:$L$501,"外人(非決済)")) -> 0 | G30: =IF($B30="","",COUNTIFS('全体集計(入力)触るな(大阪)'!$M$2:$M$501,$B30,'全体集計(入力)触るな(大阪)'!$Q$2:$Q$501,"OK")) -> 0 | H30: =IF($B30="","",COUNTIFS('全体集計(入力)触るな(大阪)'!$M$2:$M$501,$B30,'全体集計(入力)触るな(大阪)'!$L$2:$L$501,"決済",'全体集計(入力)触るな(大阪)'!$Q$2:$Q$501,"OK")+COUNTIFS('全体集計(入力)触るな(大阪)'!$M$2:$M$501,$B30,'全体集計(入力)触るな(大阪)'!$L$2:$L$501,"外人(決済)",'全体集計(入力)触るな(大阪)'!$Q$2:$Q$501,"OK")) -> 0 | I30: =IF($B30="","",COUNTIFS('全体集計(入力)触るな(大阪)'!$M$2:$M$501,$B30,'全体集計(入力)触るな(大阪)'!$Q$2:$Q$501,"NG")) -> 0 | J30: =IF($B30="","",COUNTIFS('全体集計(入力)触るな(大阪)'!$M$2:$M$501,$B30,'全体集計(入力)触るな(大阪)'!$V$2:$V$501,"リスケ")) -> 0 | K30: =IF($B30="","",COUNTIFS('全体集計(入力)触るな(大阪)'!$M$2:$M$501,$B30,'全体集計(入力)触るな(大阪)'!$W$2:$W$501,"有効商談")+COUNTIFS('全体集計(入力)触るな(大阪)'!$M$2:$M$501,$B30,'全体集計(入力)触るな(大阪)'!$W$2:$W$501,"無効商談")) -> 0 | L30: =IF($B30="","",COUNTIFS('全体集計(入力)触るな(大阪)'!$M$2:$M$501,$B30,'全体集計(入力)触るな(大阪)'!$W$2:$W$501,"有効商談")) -> 0 | M30: =IF($B30="","",COUNTIFS('全体集計(入力)触るな(大阪)'!$M$2:$M$501,$B30,'全体集計(入力)触るな(大阪)'!$W$2:$W$501,"無効商談")) -> 0 | N30: =IF($B30="","",COUNTIFS('全体集計(入力)触るな(大阪)'!$M$2:$M$501,$B30,'全体集計(入力)触るな(大阪)'!$AF$2:$AF$501,"商談キャンセル")) -> 0 | O30: =IF($B30="","",COUNTIFS('全体集計(入力)触るな(大阪)'!$M$2:$M$501,$B30,'全体集計(入力)触るな(大阪)'!$Z$2:$Z$501,"決済者")) -> 0 | P30: =IF($B30="","",COUNTIFS('全体集計(入力)触るな(大阪)'!$M$2:$M$501,$B30,'全体集計(入力)触るな(大阪)'!$AF$2:$AF$501,"失注")) -> 0 | Q30: =IF($B30="","",COUNTIFS('全体集計(入力)触るな(大阪)'!$M$2:$M$501,$B30,'全体集計(入力)触るな(大阪)'!$W$2:$W$501,"有効商談",'全体集計(入力)触るな(大阪)'!$AF$2:$AF$501,"失注")) -> 0 | R30: =IF($B30="","",COUNTIFS('全体集計(入力)触るな(大阪)'!$M$2:$M$501,$B30,'全体集計(入力)触るな(大阪)'!$W$2:$W$501,"有効商談",'全体集計(入力)触るな(大阪)'!$X$2:$X$501,"検討")) -> 0 | S30: =IF($B30="","",COUNTIFS('全体集計(入力)触るな(大阪)'!$M$2:$M$501,$B30,'全体集計(入力)触るな(大阪)'!$AF$2:$AF$501,"受注")) -> 0 | T30: =IF($B30="","",COUNTIFS('全体集計(入力)触るな(大阪)'!$M$2:$M$501,$B30,'全体集計(入力)触るな(大阪)'!$AC$2:$AC$501,"⚪︎")) -> 0 | U30: =IF($B30="","",SUMIFS('全体集計(入力)触るな(大阪)'!$AD$2:$AD$501,'全体集計(入力)触るな(大阪)'!$M$2:$M$501,$B30,'全体集計(入力)触るな(大阪)'!$AF$2:$AF$501,"受注")) -> 0 | V30: =IF($B30="","",INT(U30/10000)) -> 0 | W30: =IF($B30="","",SUMIFS(シフト入力!$N$2:$N$1501,シフト入力!$B$2:$B$1501,$B30,シフト入力!$A$2:$A$1501,"<="&TODAY())) -> 0 | X30: =IF($B30="","",IFERROR(C30/W30,0)) -> 0 | Y30: =IF($B30="","",IFERROR(G30/C30,0)) -> 0 | Z30: =IF($B30="","",IFERROR(S30/C30,0)) -> 0
B31: =IF(INDEX(マスタ!$A$2:$A$60,15)="","",INDEX(マスタ!$A$2:$A$60,15)) -> 浅妻 | C31: =IF($B31="","",COUNTIFS('全体集計(入力)触るな(大阪)'!$M$2:$M$501,$B31,'全体集計(入力)触るな(大阪)'!$L$2:$L$501,"<>")) -> 0 | D31: =IF($B31="","",COUNTIFS('全体集計(入力)触るな(大阪)'!$M$2:$M$501,$B31,'全体集計(入力)触るな(大阪)'!$L$2:$L$501,"決済")+COUNTIFS('全体集計(入力)触るな(大阪)'!$M$2:$M$501,$B31,'全体集計(入力)触るな(大阪)'!$L$2:$L$501,"外人(決済)")) -> 0 | E31: =IF($B31="","",COUNTIFS('全体集計(入力)触るな(大阪)'!$M$2:$M$501,$B31,'全体集計(入力)触るな(大阪)'!$L$2:$L$501,"非決済")+COUNTIFS('全体集計(入力)触るな(大阪)'!$M$2:$M$501,$B31,'全体集計(入力)触るな(大阪)'!$L$2:$L$501,"外人(非決済)")) -> 0 | F31: =IF($B31="","",COUNTIFS('全体集計(入力)触るな(大阪)'!$M$2:$M$501,$B31,'全体集計(入力)触るな(大阪)'!$L$2:$L$501,"外人(決済)")+COUNTIFS('全体集計(入力)触るな(大阪)'!$M$2:$M$501,$B31,'全体集計(入力)触るな(大阪)'!$L$2:$L$501,"外人(非決済)")) -> 0 | G31: =IF($B31="","",COUNTIFS('全体集計(入力)触るな(大阪)'!$M$2:$M$501,$B31,'全体集計(入力)触るな(大阪)'!$Q$2:$Q$501,"OK")) -> 0 | H31: =IF($B31="","",COUNTIFS('全体集計(入力)触るな(大阪)'!$M$2:$M$501,$B31,'全体集計(入力)触るな(大阪)'!$L$2:$L$501,"決済",'全体集計(入力)触るな(大阪)'!$Q$2:$Q$501,"OK")+COUNTIFS('全体集計(入力)触るな(大阪)'!$M$2:$M$501,$B31,'全体集計(入力)触るな(大阪)'!$L$2:$L$501,"外人(決済)",'全体集計(入力)触るな(大阪)'!$Q$2:$Q$501,"OK")) -> 0 | I31: =IF($B31="","",COUNTIFS('全体集計(入力)触るな(大阪)'!$M$2:$M$501,$B31,'全体集計(入力)触るな(大阪)'!$Q$2:$Q$501,"NG")) -> 0 | J31: =IF($B31="","",COUNTIFS('全体集計(入力)触るな(大阪)'!$M$2:$M$501,$B31,'全体集計(入力)触るな(大阪)'!$V$2:$V$501,"リスケ")) -> 0 | K31: =IF($B31="","",COUNTIFS('全体集計(入力)触るな(大阪)'!$M$2:$M$501,$B31,'全体集計(入力)触るな(大阪)'!$W$2:$W$501,"有効商談")+COUNTIFS('全体集計(入力)触るな(大阪)'!$M$2:$M$501,$B31,'全体集計(入力)触るな(大阪)'!$W$2:$W$501,"無効商談")) -> 0 | L31: =IF($B31="","",COUNTIFS('全体集計(入力)触るな(大阪)'!$M$2:$M$501,$B31,'全体集計(入力)触るな(大阪)'!$W$2:$W$501,"有効商談")) -> 0 | M31: =IF($B31="","",COUNTIFS('全体集計(入力)触るな(大阪)'!$M$2:$M$501,$B31,'全体集計(入力)触るな(大阪)'!$W$2:$W$501,"無効商談")) -> 0 | N31: =IF($B31="","",COUNTIFS('全体集計(入力)触るな(大阪)'!$M$2:$M$501,$B31,'全体集計(入力)触るな(大阪)'!$AF$2:$AF$501,"商談キャンセル")) -> 0 | O31: =IF($B31="","",COUNTIFS('全体集計(入力)触るな(大阪)'!$M$2:$M$501,$B31,'全体集計(入力)触るな(大阪)'!$Z$2:$Z$501,"決済者")) -> 0 | P31: =IF($B31="","",COUNTIFS('全体集計(入力)触るな(大阪)'!$M$2:$M$501,$B31,'全体集計(入力)触るな(大阪)'!$AF$2:$AF$501,"失注")) -> 0 | Q31: =IF($B31="","",COUNTIFS('全体集計(入力)触るな(大阪)'!$M$2:$M$501,$B31,'全体集計(入力)触るな(大阪)'!$W$2:$W$501,"有効商談",'全体集計(入力)触るな(大阪)'!$AF$2:$AF$501,"失注")) -> 0 | R31: =IF($B31="","",COUNTIFS('全体集計(入力)触るな(大阪)'!$M$2:$M$501,$B31,'全体集計(入力)触るな(大阪)'!$W$2:$W$501,"有効商談",'全体集計(入力)触るな(大阪)'!$X$2:$X$501,"検討")) -> 0 | S31: =IF($B31="","",COUNTIFS('全体集計(入力)触るな(大阪)'!$M$2:$M$501,$B31,'全体集計(入力)触るな(大阪)'!$AF$2:$AF$501,"受注")) -> 0 | T31: =IF($B31="","",COUNTIFS('全体集計(入力)触るな(大阪)'!$M$2:$M$501,$B31,'全体集計(入力)触るな(大阪)'!$AC$2:$AC$501,"⚪︎")) -> 0 | U31: =IF($B31="","",SUMIFS('全体集計(入力)触るな(大阪)'!$AD$2:$AD$501,'全体集計(入力)触るな(大阪)'!$M$2:$M$501,$B31,'全体集計(入力)触るな(大阪)'!$AF$2:$AF$501,"受注")) -> 0 | V31: =IF($B31="","",INT(U31/10000)) -> 0 | W31: =IF($B31="","",SUMIFS(シフト入力!$N$2:$N$1501,シフト入力!$B$2:$B$1501,$B31,シフト入力!$A$2:$A$1501,"<="&TODAY())) -> 0 | X31: =IF($B31="","",IFERROR(C31/W31,0)) -> 0 | Y31: =IF($B31="","",IFERROR(G31/C31,0)) -> 0 | Z31: =IF($B31="","",IFERROR(S31/C31,0)) -> 0
B34: クローザー担当別数値（大阪のアポ経由。自アポ込みの売上・順位は「クローザーサマリー」）
B35: 担当者 | C35: 商談割り当て | D35: リスケ | E35: 商談実行 | F35: 無効商談 | G35: 商談キャンセル | H35: 有効商談(決済) | I35: 有効商談(非決) | J35: 決済者 | K35: 非決済 | L35: 外人 | M35: 失注 | N35: 検討 | O35: 受注 | P35: 合計獲得プラン | Q35: 平均獲得プラン | R35: リスケ率 | S35: 商談実行率 | T35: 有効商談率 | U35: 決済率 | V35: 失注率 | W35: 受注率 | X35: 決済受注率
B36: =IF(INDEX(マスタ!$D$2:$D$60,1)="","",INDEX(マスタ!$D$2:$D$60,1)) -> 石山 | C36: =IF($B36="","",COUNTIFS('全体集計(入力)触るな(大阪)'!$U$2:$U$501,$B36)) -> 0 | D36: =IF($B36="","",COUNTIFS('全体集計(入力)触るな(大阪)'!$U$2:$U$501,$B36,'全体集計(入力)触るな(大阪)'!$V$2:$V$501,"リスケ")) -> 0 | E36: =IF($B36="","",COUNTIFS('全体集計(入力)触るな(大阪)'!$U$2:$U$501,$B36,'全体集計(入力)触るな(大阪)'!$W$2:$W$501,"有効商談")+COUNTIFS('全体集計(入力)触るな(大阪)'!$U$2:$U$501,$B36,'全体集計(入力)触るな(大阪)'!$W$2:$W$501,"無効商談")) -> 0 | F36: =IF($B36="","",COUNTIFS('全体集計(入力)触るな(大阪)'!$U$2:$U$501,$B36,'全体集計(入力)触るな(大阪)'!$W$2:$W$501,"無効商談")) -> 0 | G36: =IF($B36="","",COUNTIFS('全体集計(入力)触るな(大阪)'!$U$2:$U$501,$B36,'全体集計(入力)触るな(大阪)'!$AF$2:$AF$501,"商談キャンセル")) -> 0 | H36: =IF($B36="","",COUNTIFS('全体集計(入力)触るな(大阪)'!$U$2:$U$501,$B36,'全体集計(入力)触るな(大阪)'!$W$2:$W$501,"有効商談",'全体集計(入力)触るな(大阪)'!$Z$2:$Z$501,"決済者")) -> 0 | I36: =IF($B36="","",COUNTIFS('全体集計(入力)触るな(大阪)'!$U$2:$U$501,$B36,'全体集計(入力)触るな(大阪)'!$W$2:$W$501,"有効商談",'全体集計(入力)触るな(大阪)'!$Z$2:$Z$501,"非決済")) -> 0 | J36: =IF($B36="","",COUNTIFS('全体集計(入力)触るな(大阪)'!$U$2:$U$501,$B36,'全体集計(入力)触るな(大阪)'!$Z$2:$Z$501,"決済者")) -> 0 | K36: =IF($B36="","",COUNTIFS('全体集計(入力)触るな(大阪)'!$U$2:$U$501,$B36,'全体集計(入力)触るな(大阪)'!$Z$2:$Z$501,"非決済")) -> 0 | L36: =IF($B36="","",COUNTIFS('全体集計(入力)触るな(大阪)'!$U$2:$U$501,$B36,'全体集計(入力)触るな(大阪)'!$AG$2:$AG$501,"外人")) -> 0 | M36: =IF($B36="","",COUNTIFS('全体集計(入力)触るな(大阪)'!$U$2:$U$501,$B36,'全体集計(入力)触るな(大阪)'!$AF$2:$AF$501,"失注")) -> 0 | N36: =IF($B36="","",COUNTIFS('全体集計(入力)触るな(大阪)'!$U$2:$U$501,$B36,'全体集計(入力)触るな(大阪)'!$X$2:$X$501,"検討")) -> 0 | O36: =IF($B36="","",COUNTIFS('全体集計(入力)触るな(大阪)'!$U$2:$U$501,$B36,'全体集計(入力)触るな(大阪)'!$AF$2:$AF$501,"受注")) -> 0 | P36: =IF($B36="","",SUMIFS('全体集計(入力)触るな(大阪)'!$AD$2:$AD$501,'全体集計(入力)触るな(大阪)'!$U$2:$U$501,$B36,'全体集計(入力)触るな(大阪)'!$AF$2:$AF$501,"受注")) -> 0 | Q36: =IF($B36="","",IFERROR(P36/O36,0)) -> 0 | R36: =IF($B36="","",IFERROR(D36/C36,0)) -> 0 | S36: =IF($B36="","",IFERROR(E36/C36,0)) -> 0 | T36: =IF($B36="","",IFERROR((H36+I36)/E36,0)) -> 0 | U36: =IF($B36="","",IFERROR(J36/E36,0)) -> 0 | V36: =IF($B36="","",IFERROR(M36/E36,0)) -> 0 | W36: =IF($B36="","",IFERROR(O36/E36,0)) -> 0 | X36: =IF($B36="","",IFERROR(O36/J36,0)) -> 0
